<?xml version="1.0" ?>
<!-- =================================================================================== -->
<!-- |    This document was autogenerated by xacro from /home/hiwin/2022_timda_dual_arm/src/timda_dual_arm/gazebo/mobile_dual_arm/urdf/mobile_dual_arm.xacro | -->
<!-- |    EDITING THIS FILE BY HAND IS NOT RECOMMENDED                                 | -->
<!-- =================================================================================== -->
<robot name="mobile_dual_arm">
    <!--<xacro:include filename="$(find mir_description)/urdf/include/common.gazebo.xacro" />-->
    <!-- ros_control plugin -->
    <!--gazebo>
    <plugin name="gazebo_ros_control" filename="libgazebo_ros_control.so">
      <robotNamespace>/urdf_0129</robotNamespace>
      <robotSimType>gazebo_ros_control/DefaultRobotHWSim</robotSimType>
      <legacyModeNS>true</legacyModeNS>
    </plugin>
  </gazebo-->
    <!-- camera_link -->
    <!--gazebo reference="camera_link">
    <mu1>0.2</mu1>
    <mu2>0.2</mu2>
    <material>Gazebo/Red</material>
    <selfCollide>false</selfCollide>
  </gazebo-->
    <!-- hokuyo -->
    <!--gazebo reference="hokuyo_link">
    <sensor type="gpu_ray" name="head_hokuyo_sensor">
      <pose>0 0 0 0 0 0</pose>
      <visualize>false</visualize>
      <update_rate>40</update_rate>
      <ray>
        <scan>
          <horizontal>
            <samples>720</samples>
            <resolution>1</resolution>
            <min_angle>-1.570796</min_angle>
            <max_angle>1.570796</max_angle>
          </horizontal>
        </scan>
        <range>
          <min>0.10</min>
          <max>30.0</max>
          <resolution>0.01</resolution>
        </range>
        <noise>
          <type>gaussian</type>
          <!- Noise parameters based on published spec for Hokuyo laser
               achieving "+-30mm" accuracy at range < 10m.  A mean of 0.0m and
               stddev of 0.01m will put 99.7% of samples within 0.03m of the true
               reading. ->
          <mean>0.0</mean>
          <stddev>0.01</stddev>
        </noise>
      </ray>
      <plugin name="gazebo_ros_head_hokuyo_controller" filename="libgazebo_ros_gpu_laser.so">
        <topicName>/rrbot/laser/scan</topicName>
        <frameName>hokuyo_link</frameName>
      </plugin>
    </sensor>
  </gazebo-->
    <!-- camera -->
    <!--gazebo reference="camera_link">
    <sensor type="camera" name="camera1">
      <update_rate>30.0</update_rate>
      <camera name="head">
        <horizontal_fov>1.3962634</horizontal_fov>
        <image>
          <width>800</width>
          <height>800</height>
          <format>R8G8B8</format>
        </image>
        <clip>
          <near>0.02</near>
          <far>300</far>
        </clip>
        <noise>
          <type>gaussian</type>
          <!- Noise is sampled independently per pixel on each frame.
               That pixel's noise value is added to each of its color
               channels, which at that point lie in the range [0,1]. ->
          <mean>0.0</mean>
          <stddev>0.007</stddev>
        </noise>
      </camera>
      <plugin name="camera_controller" filename="libgazebo_ros_camera.so">
        <alwaysOn>true</alwaysOn>
        <updateRate>0.0</updateRate>
        <cameraName>urdf_0129/camera1</cameraName>
        <imageTopicName>image_raw</imageTopicName>
        <cameraInfoTopicName>camera_info</cameraInfoTopicName>
        <frameName>camera_link_optical</frameName>
        <!- setting hackBaseline to anything but 0.0 will cause a misalignment
            between the gazebo sensor image and the frame it is supposed to
            be attached to ->
        <hackBaseline>0.0</hackBaseline>
        <distortionK1>0.0</distortionK1>
        <distortionK2>0.0</distortionK2>
        <distortionK3>0.0</distortionK3>
        <distortionT1>0.0</distortionT1>
        <distortionT2>0.0</distortionT2>
        <CxPrime>0</CxPrime>
        <Cx>0.0</Cx>
        <Cy>0.0</Cy>
        <focalLength>0.0</focalLength>
      </plugin>
    </sensor>
  </gazebo-->
    <material name="black">
        <color rgba="0.0 0.0 0.0 1.0" />
    </material>
    <material name="blue">
        <color rgba="0.0 0.0 0.8 1.0" />
    </material>
    <material name="green">
        <color rgba="0.0 0.8 0.0 1.0" />
    </material>
    <material name="grey">
        <color rgba="0.2 0.2 0.2 1.0" />
    </material>
    <material name="orange">
        <color rgba="1.0 0.4235294117647059 0.0392156862745098 1.0" />
    </material>
    <material name="brown">
        <color rgba="0.8705882352941177 0.8117647058823529 0.7647058823529411 1.0" />
    </material>
    <material name="red">
        <color rgba="0.8 0.0 0.0 1.0" />
    </material>
    <material name="white">
        <color rgba="1.0 1.0 1.0 1.0" />
    </material>
    <!-- Constants for robot dimensions -->
    <gazebo reference="base_link">
        <mu1>0.2</mu1>
        <mu2>0.2</mu2>
        <material>Gazebo/Gray</material>
        <selfCollide>false</selfCollide>
        <plugin name="gazebo_ros_control">
            <robotNamespace>/</robotNamespace>
        </plugin>
    </gazebo>
    <gazebo reference="slide_right">
        <mu1>0.2</mu1>
        <mu2>0.2</mu2>
        <material>Gazebo/Black</material>
        <selfCollide>false</selfCollide>
    </gazebo>
    <gazebo reference="slide_left">
        <mu1>0.2</mu1>
        <mu2>0.2</mu2>
        <material>Gazebo/Black</material>
        <selfCollide>false</selfCollide>
    </gazebo>
    <gazebo reference="joint_right">
        <implicitSpringDamper>True</implicitSpringDamper>
    </gazebo>
    <gazebo reference="joint_left">
        <implicitSpringDamper>True</implicitSpringDamper>
    </gazebo>
    <link name="base_link">
        <inertial>
            <origin rpy="0 0 0" xyz="0.0 0 0" />
            <mass value="2.072" />
            <inertia ixx="1" ixy="0" ixz="0" iyy="1" iyz="0" izz="1" />
        </inertial>
        <visual>
            <origin rpy="0 0 0" xyz="0 0 0" />
            <geometry>
                <mesh filename="package://timda_body/meshes/base_link.STL" />
            </geometry>
            <material name="">
                <color rgba="0.79216 0.81961 0.93333 1" />
            </material>
        </visual>
        <collision>
            <origin rpy="0 0 0" xyz="0 0 0" />
            <geometry>
                <mesh filename="package://timda_body/meshes/base_link.STL" />
            </geometry>
        </collision>
    </link>
    <link name="slide_right">
        <inertial>
            <origin rpy="0 0 0" xyz="1.5718E-05 -0.006626 2.4586E-06" />
            <mass value="0.24709" />
            <inertia ixx="1" ixy="0" ixz="0" iyy="1" iyz="0" izz="1" />
        </inertial>
        <visual>
            <origin rpy="0 0 0" xyz="0 0 0" />
            <geometry>
                <mesh filename="package://timda_body/meshes/slide_right.STL" />
            </geometry>
            <material name="">
                <color rgba="0.89804 0.91765 0.92941 1" />
            </material>
        </visual>
        <collision>
            <origin rpy="0 0 0" xyz="0 0 0" />
            <geometry>
                <mesh filename="package://timda_body/meshes/slide_right.STL" />
            </geometry>
        </collision>
    </link>
    <joint name="joint_right" type="prismatic">
        <origin rpy="0 0 0" xyz="-0.2 0.0765 1.1815" />
        <parent link="base_link" />
        <child link="slide_right" />
        <axis xyz="0 0 1" />
        <limit effort="9000" lower="-0.8" upper="0" velocity="6.5" />
        <dynamics damping="7" />
    </joint>
    <link name="slide_left">
        <inertial>
            <origin rpy="0 0 0" xyz="-1.5722E-05 0.006626 2.4586E-06" />
            <mass value="0.24709" />
            <inertia ixx="1" ixy="0" ixz="0" iyy="1" iyz="0" izz="1" />
        </inertial>
        <visual>
            <origin rpy="0 0 0" xyz="0 0 0" />
            <geometry>
                <mesh filename="package://timda_body/meshes/slide_right.STL" />
            </geometry>
            <material name="">
                <color rgba="0.89804 0.91765 0.92941 1" />
            </material>
        </visual>
        <collision>
            <origin rpy="0 0 0" xyz="0 0 0" />
            <geometry>
                <mesh filename="package://timda_body/meshes/slide_right.STL" />
            </geometry>
        </collision>
    </link>
    <joint name="joint_left" type="prismatic">
        <origin rpy="0 0 3.1416" xyz="-0.2 -0.0765 1.1815" />
        <parent link="base_link" />
        <child link="slide_left" />
        <axis xyz="0 0 1" />
        <limit effort="9000" lower="-0.8" upper="0" velocity="6.5" />
        <dynamics damping="7" />
    </joint>
    <transmission name="slide_tran_r">
        <type>transmission_interface/SimpleTransmission</type>
        <joint name="joint_right">
            <hardwareInterface>hardware_interface/EffortJointInterface</hardwareInterface>
        </joint>
        <actuator name="slide_motor_r">
            <hardwareInterface>hardware_interface/EffortJointInterface</hardwareInterface>
            <mechanicalReduction>1</mechanicalReduction>
        </actuator>
    </transmission>
    <transmission name="slide_tran_l">
        <type>transmission_interface/SimpleTransmission</type>
        <joint name="joint_left">
            <hardwareInterface>hardware_interface/EffortJointInterface</hardwareInterface>
        </joint>
        <actuator name="slide_motor_l">
            <hardwareInterface>hardware_interface/EffortJointInterface</hardwareInterface>
            <mechanicalReduction>1</mechanicalReduction>
        </actuator>
    </transmission>
    <!-- ros_control plugin -->
    <!--gazebo>
    <plugin name="gazebo_ros_control" filename="libgazebo_ros_control.so">
      <robotNamespace>/urdf_0129</robotNamespace>
      <robotSimType>gazebo_ros_control/DefaultRobotHWSim</robotSimType>
    </plugin>
  </gazebo-->
    <physics type="ode">
        <max_step_size>0.001</max_step_size>
        <real_time_factor>0.1</real_time_factor>
        <real_time_update_rate>1000</real_time_update_rate>
        <gravity>0 0 -9.8</gravity>
    </physics>
    <!-- ros_control plugin -->
    <gazebo>
        <plugin filename="libgazebo_ros_control.so" name="gazebo_ros_control">
            <robotNamespace>/mobile_dual_arm</robotNamespace>
            <robotSimType>gazebo_ros_control/DefaultRobotHWSim</robotSimType>
        </plugin>
    </gazebo>
    <gazebo>
        <plugin filename="libgazebo_ros_vacuum_gripper.so" name="gazebo_ros_vacuum_gripper">
            <robotNamespace>/robot/left_gazebo/vacuum_gripper1</robotNamespace>
            <bodyName>l_end_Link1</bodyName>
            <topicName>grasping</topicName>
            <maxForce>50</maxForce>
            <maxDistance>0.05</maxDistance>
            <minDistance>0.01</minDistance>
        </plugin>
    </gazebo>
    <gazebo>
        <plugin filename="libgazebo_ros_vacuum_gripper.so" name="gazebo_ros_vacuum_gripper">
            <robotNamespace>/robot/left_gazebo/vacuum_gripper2</robotNamespace>
            <bodyName>l_end_Link2</bodyName>
            <topicName>grasping</topicName>
            <maxForce>50</maxForce>
            <maxDistance>0.05</maxDistance>
            <minDistance>0.01</minDistance>
        </plugin>
    </gazebo>
    <gazebo>
        <plugin filename="libgazebo_ros_vacuum_gripper.so" name="gazebo_ros_vacuum_gripper">
            <robotNamespace>/robot/left_gazebo/vacuum_gripper3</robotNamespace>
            <bodyName>l_end_Link3</bodyName>
            <topicName>grasping</topicName>
            <maxForce>50</maxForce>
            <maxDistance>0.05</maxDistance>
            <minDistance>0.01</minDistance>
        </plugin>
    </gazebo>
    <gazebo>
        <plugin filename="libgazebo_ros_vacuum_gripper.so" name="gazebo_ros_vacuum_gripper">
            <robotNamespace>/robot/left_gazebo/vacuum_gripper4</robotNamespace>
            <bodyName>l_end_Link4</bodyName>
            <topicName>grasping</topicName>
            <maxForce>50</maxForce>
            <maxDistance>0.05</maxDistance>
            <minDistance>0.01</minDistance>
        </plugin>
    </gazebo>
    <gazebo>
        <plugin filename="libgazebo_ros_vacuum_gripper.so" name="gazebo_ros_vacuum_gripper">
            <robotNamespace>/robot/left_gazebo/vacuum_gripper5</robotNamespace>
            <bodyName>l_end_Link5</bodyName>
            <topicName>grasping</topicName>
            <maxForce>50</maxForce>
            <maxDistance>0.05</maxDistance>
            <minDistance>0.01</minDistance>
        </plugin>
    </gazebo>
    <gazebo>
        <plugin filename="libgazebo_ros_vacuum_gripper.so" name="gazebo_ros_vacuum_gripper">
            <robotNamespace>/robot/right_gazebo/vacuum_gripper1</robotNamespace>
            <bodyName>r_end_Link1</bodyName>
            <topicName>grasping</topicName>
            <maxForce>50</maxForce>
            <maxDistance>0.05</maxDistance>
            <minDistance>0.01</minDistance>
        </plugin>
    </gazebo>
    <gazebo>
        <plugin filename="libgazebo_ros_vacuum_gripper.so" name="gazebo_ros_vacuum_gripper">
            <robotNamespace>/robot/right_gazebo/vacuum_gripper2</robotNamespace>
            <bodyName>r_end_Link2</bodyName>
            <topicName>grasping</topicName>
            <maxForce>50</maxForce>
            <maxDistance>0.05</maxDistance>
            <minDistance>0.01</minDistance>
        </plugin>
    </gazebo>
    <gazebo>
        <plugin filename="libgazebo_ros_vacuum_gripper.so" name="gazebo_ros_vacuum_gripper">
            <robotNamespace>/robot/right_gazebo/vacuum_gripper3</robotNamespace>
            <bodyName>r_end_Link3</bodyName>
            <topicName>grasping</topicName>
            <maxForce>50</maxForce>
            <maxDistance>0.05</maxDistance>
            <minDistance>0.01</minDistance>
        </plugin>
    </gazebo>
    <gazebo>
        <plugin filename="libgazebo_ros_vacuum_gripper.so" name="gazebo_ros_vacuum_gripper">
            <robotNamespace>/robot/right_gazebo/vacuum_gripper4</robotNamespace>
            <bodyName>r_end_Link4</bodyName>
            <topicName>grasping</topicName>
            <maxForce>50</maxForce>
            <maxDistance>0.05</maxDistance>
            <minDistance>0.01</minDistance>
        </plugin>
    </gazebo>
    <gazebo>
        <plugin filename="libgazebo_ros_vacuum_gripper.so" name="gazebo_ros_vacuum_gripper">
            <robotNamespace>/robot/right_gazebo/vacuum_gripper5</robotNamespace>
            <bodyName>r_end_Link5</bodyName>
            <topicName>grasping</topicName>
            <maxForce>50</maxForce>
            <maxDistance>0.05</maxDistance>
            <minDistance>0.01</minDistance>
        </plugin>
    </gazebo>
    <gazebo reference="Bin">
        <mu1>200</mu1>
        <mu2>200</mu2>
        <material>Gazebo/Blue</material>
        <selfCollide>false</selfCollide>
    </gazebo>
    <!--====================================================================================

<gazebo reference="Base">
    <mu1>0.5</mu1>
    <mu2>0.5</mu2>
    <material>Gazebo/Orange</material>
    <selfCollide>false</selfCollide>
  </gazebo>

  
  <gazebo reference="Link_1">
    <mu1>0.5</mu1>
    <mu2>0.5</mu2>
    <material>Gazebo/Black</material>
    <selfCollide>false</selfCollide>
  </gazebo>

 
  <gazebo reference="Link_2">
    <mu1>0.5</mu1>
    <mu2>0.5</mu2>
    <material>Gazebo/Orange</material>
    <selfCollide>false</selfCollide>
  </gazebo>

  <gazebo reference="Link_3">
    <mu1>0.5</mu1>
    <mu2>0.5</mu2>
    <material>Gazebo/Black</material>
    <selfCollide>false</selfCollide>
  </gazebo>

  <gazebo reference="Link_4">
    <mu1>0.5</mu1>
    <mu2>0.5</mu2>
    <material>Gazebo/Orange</material>
    <selfCollide>false</selfCollide>
  </gazebo>

  <gazebo reference="Link_5">
    <mu1>0.5</mu1>
    <mu2>0.5</mu2>
    <material>Gazebo/Black</material>
    <selfCollide>false</selfCollide>
  </gazebo>

  <gazebo reference="Link_6">
    <mu1>0.5</mu1>
    <mu2>0.5</mu2>
    <material>Gazebo/Orange</material>
    <selfCollide>false</selfCollide>
  </gazebo>



  
  <gazebo reference="Arm_Base_R">
    <mu1>0.5</mu1>
    <mu2>0.5</mu2>
    <material>Gazebo/Orange</material>
    <selfCollide>false</selfCollide>
  </gazebo>

 
  <gazebo reference="Link_R_1">
    <mu1>0.5</mu1>
    <mu2>0.5</mu2>
    <material>Gazebo/Black</material>
    <selfCollide>false</selfCollide>
  </gazebo>

  
  <gazebo reference="Link_R_2">
    <mu1>0.5</mu1>
    <mu2>0.5</mu2>
    <material>Gazebo/Orange</material>
    <selfCollide>false</selfCollide>
  </gazebo>

  <gazebo reference="Link_R_3">
    <mu1>0.5</mu1>
    <mu2>0.5</mu2>
    <material>Gazebo/Black</material>
    <selfCollide>false</selfCollide>
  </gazebo>

  <gazebo reference="Link_R_4">
    <mu1>0.5</mu1>
    <mu2>0.5</mu2>
    <material>Gazebo/Orange</material>
    <selfCollide>false</selfCollide>
  </gazebo>

  <gazebo reference="Link_R_5">
    <mu1>0.5</mu1>
    <mu2>0.5</mu2>
    <material>Gazebo/Black</material>
    <selfCollide>false</selfCollide>
  </gazebo>

  <gazebo reference="Link_R_6">
    <mu1>0.5</mu1>
    <mu2>0.5</mu2>
    <material>Gazebo/Orange</material>
    <selfCollide>false</selfCollide>
  </gazebo>

================================================================-->
    <!--
  <gazebo reference="Link_7">
    <mu1>0.2</mu1>
    <mu2>0.2</mu2>
    <material>Gazebo/Black</material>
    <selfCollide>true</selfCollide>
  </gazebo>

  <gazebo reference="Link_8">
    <mu1>0.2</mu1>
    <mu2>0.2</mu2>
    <material>Gazebo/Orange</material>
    <selfCollide>false</selfCollide>
  </gazebo>
-->
    <!-- camera_link -->
    <!--gazebo reference="camera_link">
    <mu1>0.2</mu1>
    <mu2>0.2</mu2>
    <material>Gazebo/Red</material>
    <selfCollide>false</selfCollide>
  </gazebo-->
    <!-- hokuyo -->
    <!--gazebo reference="hokuyo_link">
    <sensor type="gpu_ray" name="head_hokuyo_sensor">
      <pose>0 0 0 0 0 0</pose>
      <visualize>false</visualize>
      <update_rate>40</update_rate>
      <ray>
        <scan>
          <horizontal>
            <samples>720</samples>
            <resolution>1</resolution>
            <min_angle>-1.570796</min_angle>
            <max_angle>1.570796</max_angle>
          </horizontal>
        </scan>
        <range>
          <min>0.10</min>
          <max>30.0</max>
          <resolution>0.01</resolution>
        </range>
        <noise>
          <type>gaussian</type>
          <!- Noise parameters based on published spec for Hokuyo laser
               achieving "+-30mm" accuracy at range < 10m.  A mean of 0.0m and
               stddev of 0.01m will put 99.7% of samples within 0.03m of the true
               reading. ->
          <mean>0.0</mean>
          <stddev>0.01</stddev>
        </noise>
      </ray>
      <plugin name="gazebo_ros_head_hokuyo_controller" filename="libgazebo_ros_gpu_laser.so">
        <topicName>/rrbot/laser/scan</topicName>
        <frameName>hokuyo_link</frameName>
      </plugin>
    </sensor>
  </gazebo-->
    <!-- camera -->
    <!--gazebo reference="camera_link">
    <sensor type="camera" name="camera1">
      <update_rate>30.0</update_rate>
      <camera name="head">
        <horizontal_fov>1.3962634</horizontal_fov>
        <image>
          <width>800</width>
          <height>800</height>
          <format>R8G8B8</format>
        </image>
        <clip>
          <near>0.02</near>
          <far>300</far>
        </clip>
        <noise>
          <type>gaussian</type>
          <!- Noise is sampled independently per pixel on each frame.
               That pixel's noise value is added to each of its color
               channels, which at that point lie in the range [0,1]. ->
          <mean>0.0</mean>
          <stddev>0.007</stddev>
        </noise>
      </camera>
      <plugin name="camera_controller" filename="libgazebo_ros_camera.so">
        <alwaysOn>true</alwaysOn>
        <updateRate>0.0</updateRate>
        <cameraName>urdf_0129/camera1</cameraName>
        <imageTopicName>image_raw</imageTopicName>
        <cameraInfoTopicName>camera_info</cameraInfoTopicName>
        <frameName>camera_link_optical</frameName>
        <!- setting hackBaseline to anything but 0.0 will cause a misalignment
            between the gazebo sensor image and the frame it is supposed to
            be attached to ->
        <hackBaseline>0.0</hackBaseline>
        <distortionK1>0.0</distortionK1>
        <distortionK2>0.0</distortionK2>
        <distortionK3>0.0</distortionK3>
        <distortionT1>0.0</distortionT1>
        <distortionT2>0.0</distortionT2>
        <CxPrime>0</CxPrime>
        <Cx>0.0</Cx>
        <Cy>0.0</Cy>
        <focalLength>0.0</focalLength>
      </plugin>
    </sensor>
  </gazebo-->
    <!--xacro:include filename="$(find mobile_table)/urdf/mobile_table.xacro" /-->
    <link name="world" />
    <joint name="fixed1" type="fixed">
        <origin rpy="0 0 0" xyz="0 0 0" />
        <parent link="world" />
        <child link="mobile_base_footprint" />
    </joint>
    <joint name="fixed3" type="fixed">
        <origin rpy="0 0 0" xyz="0.037646 0.0 0.355" />
        <!--0.037646-->
        <!--<origin
      xyz="0 0 0.562"
      rpy="0 0 0" /-->
        <parent link="mobile_base_footprint" />
        <child link="base_link" />
    </joint>
    <link name="mobile_base_footprint" />
    <joint name="mobile_base_joint" type="fixed">
        <parent link="mobile_base_footprint" />
        <child link="mobile_base_link" />
        <origin rpy="0 0 0" xyz="0 0 0" />
    </joint>
    <link name="mobile_base_link">
        <inertial>
            <mass value="58.0" />
            <origin rpy="0 0 0" xyz="0.037646 0 0.20" />
            <inertia ixx="2.0609325089599997" ixy="0.0" ixz="0.0" iyy="4.34999826" iyz="0.0" izz="5.54093111696" />
        </inertial>
        <visual>
            <origin rpy="0 0 0" xyz="0.037646 0 0" />
            <geometry>
                <mesh filename="package://mir_description/meshes/visual/mir_100_base.stl" />
            </geometry>
            <material name="white">
                <color rgba="1 1 1 1" />
            </material>
        </visual>
        <collision>
            <origin rpy="0 0 0" xyz="0.037646 0 0" />
            <geometry>
                <mesh filename="package://mir_description/meshes/collision/mir_100_base.stl" />
            </geometry>
        </collision>
    </link>
    <gazebo reference="mobile_base_link">
        <material>Gazebo/White</material>
    </gazebo>
    <!-- IMU -->
    <joint name="mobile_base_link_to_imu_joint" type="fixed">
        <parent link="mobile_base_link" />
        <child link="mobile_imu_link" />
        <origin rpy="0 0 0" xyz="0.0 0.0 0.25" />
        <!-- same as real MiR -->
    </joint>
    <link name="mobile_imu_link" />
    <gazebo reference="mobile_imu_link">
        <gravity>true</gravity>
        <sensor name="imu_sensor" type="imu">
            <always_on>true</always_on>
            <update_rate>100</update_rate>
            <!-- this is not the publish rate -->
            <visualize>true</visualize>
            <topic>__default_topic__</topic>
            <plugin filename="libgazebo_ros_imu_sensor.so" name="imu_plugin">
                <topicName>imu_data</topicName>
                <bodyName>mobile_imu_link</bodyName>
                <updateRateHZ>50.0</updateRateHZ>
                <!-- this is the publish rate -->
                <gaussianNoise>2.8900000000000004e-08</gaussianNoise>
                <xyzOffset>0 0 0</xyzOffset>
                <rpyOffset>0 0 0</rpyOffset>
                <frameName>imu_frame</frameName>
                <!-- from real MiR -->
            </plugin>
            <pose>0 0 0 0 0 0</pose>
        </sensor>
    </gazebo>
    <!-- Create an alias for imu_link. This is necessary because the real MiR's
         TF has imu_link, but the imu_data topic is published in the imu_frame
         frame. -->
    <joint name="mobile_imu_link_to_imu_frame_joint" type="fixed">
        <parent link="mobile_imu_link" />
        <child link="mobile_imu_frame" />
        <origin rpy="0 0 0" xyz="0 0 0" />
    </joint>
    <link name="mobile_imu_frame" />
    <!-- Laser scanners -->
    <joint name="mobile_base_link_to_front_laser_joint" type="fixed">
        <parent link="mobile_base_link" />
        <child link="mobile_front_laser_link" />
        <origin rpy="0.0 0.0 0.7853981633974483" xyz="0.4288 0.2358 0.1914" />
        <!-- from visually matching up the meshes of the MiR and the laser scanner -->
    </joint>
    <link name="mobile_front_laser_link">
        <visual>
            <origin rpy="3.141592653589793 0 0" xyz="0.0 0.0 0.0" />
            <geometry>
                <mesh filename="package://mir_description/meshes/visual/sick_lms-100.stl" />
            </geometry>
            <!-- <xacro:insert_block name="material_yellow" /> -->
            <material name="black">
                <color rgba="0.1 0.1 0.1 1" />
            </material>
        </visual>
        <collision>
            <origin rpy="3.141592653589793 0 0" xyz="0.0 0.0 0.0" />
            <geometry>
                <mesh filename="package://mir_description/meshes/visual/sick_lms-100.stl" />
            </geometry>
        </collision>
        <inertial>
            <mass value="2.0" />
            <origin xyz="0 0 0" rpy="0 0 0" />
            <inertia ixx="0.009708329449999999" ixy="0.0" ixz="0.0" iyy="0.0097601627626" iyz="0.0" izz="0.0080601634426" />
        </inertial>
    </link>
    <gazebo reference="mobile_front_laser_link">
        <!-- <material value="Gazebo/Yellow" /> -->
        <material value="Gazebo/FlatBlack" />
        <sensor name="mobile_front_laser_link" type="gpu_ray">
            <pose>0 0 0 0 0 0</pose>
            <visualize>false</visualize>
            <update_rate>12.5</update_rate>
            <ray>
                <scan>
                    <horizontal>
                        <samples>541</samples>
                        <resolution>1</resolution>
                        <!-- has to be 1; actual resolution will be computed from number of samples + min_angle/max_angle -->
                        <min_angle>-2.35619449615</min_angle>
                        <max_angle>2.35619449615</max_angle>
                    </horizontal>
                </scan>
                <range>
                    <min>0.05</min>
                    <max>29.0</max>
                    <resolution>0.01</resolution>
                </range>
                <noise>
                    <type>gaussian</type>
                    <!-- Noise parameters based on published spec for S300 achieving
                 "+-29mm" accuracy at range < 3m (~0.01 of the range) at
                 1 sigma. -->
                    <mean>0.0</mean>
                    <stddev>0.01</stddev>
                </noise>
            </ray>
            <plugin filename="libgazebo_ros_gpu_laser.so" name="gazebo_ros_front_laser_link_controller">
                <!-- no prefix, plugin always uses a tf_prefix (if none is set it uses robotNamespace) -->
                <frameName>front_laser_link</frameName>
                <topicName>f_scan</topicName>
            </plugin>
        </sensor>
    </gazebo>
    <joint name="mobile_base_link_to_back_laser_joint" type="fixed">
        <parent link="mobile_base_link" />
        <child link="mobile_back_laser_link" />
        <origin rpy="0.0 0.0 -2.356194490192345" xyz="-0.3548 -0.2352 0.1914" />
        <!-- from visually matching up the meshes of the MiR and the laser scanner -->
    </joint>
    <link name="mobile_back_laser_link">
        <visual>
            <origin rpy="3.141592653589793 0 0" xyz="0.0 0.0 0.0" />
            <geometry>
                <mesh filename="package://mir_description/meshes/visual/sick_lms-100.stl" />
            </geometry>
            <!-- <xacro:insert_block name="material_yellow" /> -->
            <material name="black">
                <color rgba="0.1 0.1 0.1 1" />
            </material>
        </visual>
        <collision>
            <origin rpy="3.141592653589793 0 0" xyz="0.0 0.0 0.0" />
            <geometry>
                <mesh filename="package://mir_description/meshes/visual/sick_lms-100.stl" />
            </geometry>
        </collision>
        <inertial>
            <mass value="2.0" />
            <origin xyz="0 0 0" rpy="0 0 0" />
            <inertia ixx="0.009708329449999999" ixy="0.0" ixz="0.0" iyy="0.0097601627626" iyz="0.0" izz="0.0080601634426" />
        </inertial>
    </link>
    <gazebo reference="mobile_back_laser_link">
        <!-- <material value="Gazebo/Yellow" /> -->
        <material value="Gazebo/FlatBlack" />
        <sensor name="mobile_back_laser_link" type="gpu_ray">
            <pose>0 0 0 0 0 0</pose>
            <visualize>false</visualize>
            <update_rate>12.5</update_rate>
            <ray>
                <scan>
                    <horizontal>
                        <samples>541</samples>
                        <resolution>1</resolution>
                        <!-- has to be 1; actual resolution will be computed from number of samples + min_angle/max_angle -->
                        <min_angle>-2.35619449615</min_angle>
                        <max_angle>2.35619449615</max_angle>
                    </horizontal>
                </scan>
                <range>
                    <min>0.05</min>
                    <max>29.0</max>
                    <resolution>0.01</resolution>
                </range>
                <noise>
                    <type>gaussian</type>
                    <!-- Noise parameters based on published spec for S300 achieving
                 "+-29mm" accuracy at range < 3m (~0.01 of the range) at
                 1 sigma. -->
                    <mean>0.0</mean>
                    <stddev>0.01</stddev>
                </noise>
            </ray>
            <plugin filename="libgazebo_ros_gpu_laser.so" name="gazebo_ros_back_laser_link_controller">
                <!-- no prefix, plugin always uses a tf_prefix (if none is set it uses robotNamespace) -->
                <frameName>back_laser_link</frameName>
                <topicName>b_scan</topicName>
            </plugin>
        </sensor>
    </gazebo>
    <!-- Ultrasound sensors -->
    <joint name="mobile_us_1_joint" type="fixed">
        <!-- right ultrasound -->
        <parent link="mobile_base_link" />
        <child link="mobile_us_1_frame" />
        <origin rpy="0 0 0" xyz="0.45 -0.12 0.16 " />
        <!-- from visually matching to the mesh of the MiR -->
    </joint>
    <link name="mobile_us_1_frame" />
    <joint name="mobile_us_2_joint" type="fixed">
        <!-- left ultrasound -->
        <parent link="mobile_base_link" />
        <child link="mobile_us_2_frame" />
        <origin rpy="0 0 0" xyz="0.45 0.12 0.16 " />
        <!-- from visually matching to the mesh of the MiR -->
    </joint>
    <link name="mobile_us_2_frame" />
    <joint name="mobile_left_wheel_joint" type="continuous">
        <origin rpy="0 0 0" xyz="0.0 0.222604 0.0625" />
        <parent link="mobile_base_link" />
        <child link="mobile_left_wheel_link" />
        <axis xyz="0 1 0" />
        <limit effort="100" velocity="20.0" />
    </joint>
    <link name="mobile_left_wheel_link">
        <inertial>
            <mass value="1.0" />
            <origin rpy="1.5707963267948966 0 0" xyz="0 0 0" />
            <inertia ixx="0.001061895408575" ixy="0.0" ixz="0.0" iyy="0.001061895408575" iyz="0.0" izz="0.001953125" />
        </inertial>
        <visual>
            <origin rpy="0 0 0" xyz="0 0 0" />
            <geometry>
                <mesh filename="package://mir_description/meshes/visual/wheel.stl" />
            </geometry>
            <material name="dark_grey">
                <color rgba="0.3 0.3 0.3 1" />
            </material>
        </visual>
        <collision>
            <origin rpy="0 0 0" xyz="0 0 0" />
            <geometry>
                <mesh filename="package://mir_description/meshes/visual/wheel.stl" />
            </geometry>
        </collision>
    </link>
    <gazebo reference="mobile_left_wheel_link">
        <material>Gazebo/DarkGrey</material>
    </gazebo>
    <joint name="mobile_right_wheel_joint" type="continuous">
        <origin rpy="0 0 0" xyz="0.0 -0.222604 0.0625" />
        <parent link="mobile_base_link" />
        <child link="mobile_right_wheel_link" />
        <axis xyz="0 1 0" />
        <limit effort="100" velocity="20.0" />
    </joint>
    <link name="mobile_right_wheel_link">
        <inertial>
            <mass value="1.0" />
            <origin rpy="1.5707963267948966 0 0" xyz="0 0 0" />
            <inertia ixx="0.001061895408575" ixy="0.0" ixz="0.0" iyy="0.001061895408575" iyz="0.0" izz="0.001953125" />
        </inertial>
        <visual>
            <origin rpy="0 0 0" xyz="0 0 0" />
            <geometry>
                <mesh filename="package://mir_description/meshes/visual/wheel.stl" />
            </geometry>
            <material name="dark_grey">
                <color rgba="0.3 0.3 0.3 1" />
            </material>
        </visual>
        <collision>
            <origin rpy="0 0 0" xyz="0 0 0" />
            <geometry>
                <mesh filename="package://mir_description/meshes/visual/wheel.stl" />
            </geometry>
        </collision>
    </link>
    <gazebo reference="mobile_right_wheel_link">
        <material>Gazebo/DarkGrey</material>
    </gazebo>
    <!-- caster hub -->
    <joint name="mobile_fl_caster_rotation_joint" type="continuous">
        <origin rpy="0 0 0" xyz="0.341346 0.203 0.1565" />
        <parent link="mobile_base_link" />
        <child link="mobile_fl_caster_rotation_link" />
        <axis xyz="0 0 1" />
        <dynamics damping="0.01" friction="0.0" />
    </joint>
    <link name="mobile_fl_caster_rotation_link">
        <inertial>
            <!-- <origin xyz="0 0 -0.042500000044" rpy="${0.5 * pi} ${24 * deg_to_rad} ${1.5 * pi}" /> -->
            <origin rpy="0.41887903200000004 0 1.5707963267948966 " xyz="0 0 -0.042500000044" />
            <mass value="0.3097539019" />
            <inertia ixx="0.0005844517978" ixy="0" ixz="0" iyy="0.00052872551237" iyz="0" izz="0.00017923555074" />
        </inertial>
        <visual>
            <origin rpy="0 0 0" xyz="0 0 0" />
            <geometry>
                <mesh filename="package://mir_description/meshes/visual/caster_wheel_base.stl" />
            </geometry>
            <material name="silver">
                <color rgba="0.79 0.82 0.93 1" />
            </material>
        </visual>
        <collision>
            <origin rpy="0 0 0" xyz="0 0 0" />
            <geometry>
                <mesh filename="package://mir_description/meshes/collision/caster_wheel_base.stl" />
            </geometry>
        </collision>
    </link>
    <gazebo reference="mobile_fl_caster_rotation_link">
        <material>Gazebo/Grey</material>
    </gazebo>
    <!-- caster wheel -->
    <joint name="mobile_fl_caster_wheel_joint" type="continuous">
        <origin rpy="0 0 0" xyz="-0.0382 0 -0.094" />
        <parent link="mobile_fl_caster_rotation_link" />
        <child link="mobile_fl_caster_wheel_link" />
        <axis xyz="0 1 0" />
    </joint>
    <link name="mobile_fl_caster_wheel_link">
        <inertial>
            <mass value="1.0" />
            <origin rpy="1.5707963267948966 0 0" xyz="0 0 0" />
            <inertia ixx="0.001061895408575" ixy="0.0" ixz="0.0" iyy="0.001061895408575" iyz="0.0" izz="0.001953125" />
        </inertial>
        <visual>
            <origin rpy="0 0 0" xyz="0 0 0" />
            <geometry>
                <mesh filename="package://mir_description/meshes/visual/wheel.stl" />
            </geometry>
            <material name="dark_grey">
                <color rgba="0.3 0.3 0.3 1" />
            </material>
        </visual>
        <collision>
            <origin rpy="0 0 0" xyz="0 0 0" />
            <geometry>
                <mesh filename="package://mir_description/meshes/visual/wheel.stl" />
            </geometry>
        </collision>
    </link>
    <gazebo reference="mobile_fl_caster_wheel_link">
        <material>Gazebo/DarkGrey</material>
    </gazebo>
    <!-- caster hub -->
    <joint name="mobile_fr_caster_rotation_joint" type="continuous">
        <origin rpy="0 0 0" xyz="0.341346 -0.203 0.1565" />
        <parent link="mobile_base_link" />
        <child link="mobile_fr_caster_rotation_link" />
        <axis xyz="0 0 1" />
        <dynamics damping="0.01" friction="0.0" />
    </joint>
    <link name="mobile_fr_caster_rotation_link">
        <inertial>
            <!-- <origin xyz="0 0 -0.042500000044" rpy="${0.5 * pi} ${24 * deg_to_rad} ${1.5 * pi}" /> -->
            <origin rpy="0.41887903200000004 0 1.5707963267948966 " xyz="0 0 -0.042500000044" />
            <mass value="0.3097539019" />
            <inertia ixx="0.0005844517978" ixy="0" ixz="0" iyy="0.00052872551237" iyz="0" izz="0.00017923555074" />
        </inertial>
        <visual>
            <origin rpy="0 0 0" xyz="0 0 0" />
            <geometry>
                <mesh filename="package://mir_description/meshes/visual/caster_wheel_base.stl" />
            </geometry>
            <material name="silver">
                <color rgba="0.79 0.82 0.93 1" />
            </material>
        </visual>
        <collision>
            <origin rpy="0 0 0" xyz="0 0 0" />
            <geometry>
                <mesh filename="package://mir_description/meshes/collision/caster_wheel_base.stl" />
            </geometry>
        </collision>
    </link>
    <gazebo reference="mobile_fr_caster_rotation_link">
        <material>Gazebo/Grey</material>
    </gazebo>
    <!-- caster wheel -->
    <joint name="mobile_fr_caster_wheel_joint" type="continuous">
        <origin rpy="0 0 0" xyz="-0.0382 0 -0.094" />
        <parent link="mobile_fr_caster_rotation_link" />
        <child link="mobile_fr_caster_wheel_link" />
        <axis xyz="0 1 0" />
    </joint>
    <link name="mobile_fr_caster_wheel_link">
        <inertial>
            <mass value="1.0" />
            <origin rpy="1.5707963267948966 0 0" xyz="0 0 0" />
            <inertia ixx="0.001061895408575" ixy="0.0" ixz="0.0" iyy="0.001061895408575" iyz="0.0" izz="0.001953125" />
        </inertial>
        <visual>
            <origin rpy="0 0 0" xyz="0 0 0" />
            <geometry>
                <mesh filename="package://mir_description/meshes/visual/wheel.stl" />
            </geometry>
            <material name="dark_grey">
                <color rgba="0.3 0.3 0.3 1" />
            </material>
        </visual>
        <collision>
            <origin rpy="0 0 0" xyz="0 0 0" />
            <geometry>
                <mesh filename="package://mir_description/meshes/visual/wheel.stl" />
            </geometry>
        </collision>
    </link>
    <gazebo reference="mobile_fr_caster_wheel_link">
        <material>Gazebo/DarkGrey</material>
    </gazebo>
    <!-- caster hub -->
    <joint name="mobile_bl_caster_rotation_joint" type="continuous">
        <origin rpy="0 0 0" xyz="-0.270154 0.203 0.1565" />
        <parent link="mobile_base_link" />
        <child link="mobile_bl_caster_rotation_link" />
        <axis xyz="0 0 1" />
        <dynamics damping="0.01" friction="0.0" />
    </joint>
    <link name="mobile_bl_caster_rotation_link">
        <inertial>
            <!-- <origin xyz="0 0 -0.042500000044" rpy="${0.5 * pi} ${24 * deg_to_rad} ${1.5 * pi}" /> -->
            <origin rpy="0.41887903200000004 0 1.5707963267948966 " xyz="0 0 -0.042500000044" />
            <mass value="0.3097539019" />
            <inertia ixx="0.0005844517978" ixy="0" ixz="0" iyy="0.00052872551237" iyz="0" izz="0.00017923555074" />
        </inertial>
        <visual>
            <origin rpy="0 0 0" xyz="0 0 0" />
            <geometry>
                <mesh filename="package://mir_description/meshes/visual/caster_wheel_base.stl" />
            </geometry>
            <material name="silver">
                <color rgba="0.79 0.82 0.93 1" />
            </material>
        </visual>
        <collision>
            <origin rpy="0 0 0" xyz="0 0 0" />
            <geometry>
                <mesh filename="package://mir_description/meshes/collision/caster_wheel_base.stl" />
            </geometry>
        </collision>
    </link>
    <gazebo reference="mobile_bl_caster_rotation_link">
        <material>Gazebo/Grey</material>
    </gazebo>
    <!-- caster wheel -->
    <joint name="mobile_bl_caster_wheel_joint" type="continuous">
        <origin rpy="0 0 0" xyz="-0.0382 0 -0.094" />
        <parent link="mobile_bl_caster_rotation_link" />
        <child link="mobile_bl_caster_wheel_link" />
        <axis xyz="0 1 0" />
    </joint>
    <link name="mobile_bl_caster_wheel_link">
        <inertial>
            <mass value="1.0" />
            <origin rpy="1.5707963267948966 0 0" xyz="0 0 0" />
            <inertia ixx="0.001061895408575" ixy="0.0" ixz="0.0" iyy="0.001061895408575" iyz="0.0" izz="0.001953125" />
        </inertial>
        <visual>
            <origin rpy="0 0 0" xyz="0 0 0" />
            <geometry>
                <mesh filename="package://mir_description/meshes/visual/wheel.stl" />
            </geometry>
            <material name="dark_grey">
                <color rgba="0.3 0.3 0.3 1" />
            </material>
        </visual>
        <collision>
            <origin rpy="0 0 0" xyz="0 0 0" />
            <geometry>
                <mesh filename="package://mir_description/meshes/visual/wheel.stl" />
            </geometry>
        </collision>
    </link>
    <gazebo reference="mobile_bl_caster_wheel_link">
        <material>Gazebo/DarkGrey</material>
    </gazebo>
    <!-- caster hub -->
    <joint name="mobile_br_caster_rotation_joint" type="continuous">
        <origin rpy="0 0 0" xyz="-0.270154 -0.203 0.1565" />
        <parent link="mobile_base_link" />
        <child link="mobile_br_caster_rotation_link" />
        <axis xyz="0 0 1" />
        <dynamics damping="0.01" friction="0.0" />
    </joint>
    <link name="mobile_br_caster_rotation_link">
        <inertial>
            <!-- <origin xyz="0 0 -0.042500000044" rpy="${0.5 * pi} ${24 * deg_to_rad} ${1.5 * pi}" /> -->
            <origin rpy="0.41887903200000004 0 1.5707963267948966 " xyz="0 0 -0.042500000044" />
            <mass value="0.3097539019" />
            <inertia ixx="0.0005844517978" ixy="0" ixz="0" iyy="0.00052872551237" iyz="0" izz="0.00017923555074" />
        </inertial>
        <visual>
            <origin rpy="0 0 0" xyz="0 0 0" />
            <geometry>
                <mesh filename="package://mir_description/meshes/visual/caster_wheel_base.stl" />
            </geometry>
            <material name="silver">
                <color rgba="0.79 0.82 0.93 1" />
            </material>
        </visual>
        <collision>
            <origin rpy="0 0 0" xyz="0 0 0" />
            <geometry>
                <mesh filename="package://mir_description/meshes/collision/caster_wheel_base.stl" />
            </geometry>
        </collision>
    </link>
    <gazebo reference="mobile_br_caster_rotation_link">
        <material>Gazebo/Grey</material>
    </gazebo>
    <!-- caster wheel -->
    <joint name="mobile_br_caster_wheel_joint" type="continuous">
        <origin rpy="0 0 0" xyz="-0.0382 0 -0.094" />
        <parent link="mobile_br_caster_rotation_link" />
        <child link="mobile_br_caster_wheel_link" />
        <axis xyz="0 1 0" />
    </joint>
    <link name="mobile_br_caster_wheel_link">
        <inertial>
            <mass value="1.0" />
            <origin rpy="1.5707963267948966 0 0" xyz="0 0 0" />
            <inertia ixx="0.001061895408575" ixy="0.0" ixz="0.0" iyy="0.001061895408575" iyz="0.0" izz="0.001953125" />
        </inertial>
        <visual>
            <origin rpy="0 0 0" xyz="0 0 0" />
            <geometry>
                <mesh filename="package://mir_description/meshes/visual/wheel.stl" />
            </geometry>
            <material name="dark_grey">
                <color rgba="0.3 0.3 0.3 1" />
            </material>
        </visual>
        <collision>
            <origin rpy="0 0 0" xyz="0 0 0" />
            <geometry>
                <mesh filename="package://mir_description/meshes/visual/wheel.stl" />
            </geometry>
        </collision>
    </link>
    <gazebo reference="mobile_br_caster_wheel_link">
        <material>Gazebo/DarkGrey</material>
    </gazebo>
    <joint name="mobile_base_link_surface_joint" type="fixed">
        <origin rpy="0 0 0" xyz="0.037646 0 0.352" />
        <parent link="mobile_base_link" />
        <child link="mobile_surface" />
        <axis xyz="0 0 1" />
    </joint>
    <link name="mobile_surface" />
    <transmission name="mobile_left_wheel_trans">
        <type>transmission_interface/SimpleTransmission</type>
        <joint name="mobile_left_wheel_joint">
            <hardwareInterface>hardware_interface/VelocityJointInterface</hardwareInterface>
        </joint>
        <actuator name="mobile_left_wheel_motor">
            <hardwareInterface>hardware_interface/VelocityJointInterface</hardwareInterface>
            <mechanicalReduction>1</mechanicalReduction>
        </actuator>
    </transmission>
    <transmission name="mobile_right_wheel_trans">
        <type>transmission_interface/SimpleTransmission</type>
        <joint name="mobile_right_wheel_joint">
            <hardwareInterface>hardware_interface/VelocityJointInterface</hardwareInterface>
        </joint>
        <actuator name="mobile_right_wheel_motor">
            <hardwareInterface>hardware_interface/VelocityJointInterface</hardwareInterface>
            <mechanicalReduction>1</mechanicalReduction>
        </actuator>
    </transmission>
    <gazebo reference="mobile_left_wheel_link">
        <mu1 value="200" />
        <mu2 value="200" />
        <kp value="10000000.0" />
        <kd value="1.0" />
        <minDepth>0.01</minDepth>
    </gazebo>
    <gazebo reference="mobile_right_wheel_link">
        <mu1 value="200" />
        <mu2 value="200" />
        <kp value="10000000.0" />
        <kd value="1.0" />
        <minDepth>0.01</minDepth>
    </gazebo>
    <gazebo reference="mobile_fl_caster_wheel_link">
        <mu1 value="100" />
        <mu2 value="100" />
        <kp value="10000000.0" />
        <kd value="1.0" />
        <minDepth>0.01</minDepth>
    </gazebo>
    <gazebo reference="mobile_fr_caster_wheel_link">
        <mu1 value="100" />
        <mu2 value="100" />
        <kp value="10000000.0" />
        <kd value="1.0" />
        <minDepth>0.01</minDepth>
    </gazebo>
    <gazebo reference="mobile_bl_caster_wheel_link">
        <mu1 value="100" />
        <mu2 value="100" />
        <kp value="10000000.0" />
        <kd value="1.0" />
        <minDepth>0.01</minDepth>
    </gazebo>
    <gazebo reference="mobile_br_caster_wheel_link">
        <mu1 value="100" />
        <mu2 value="100" />
        <kp value="10000000.0" />
        <kd value="1.0" />
        <minDepth>0.01</minDepth>
    </gazebo>
    <p3d_base_controller prefix="mobile_" />
    <link name="r_Base">
        <inertial>
            <origin rpy="0 0 0" xyz="0.000156250860732315 0.000202963757501797 -0.0546720420122521" />
            <mass value="0.323603974032196" />
            <inertia ixx="0.1" ixy="0.0" ixz="0.0" iyy="0.1" iyz="0.0" izz="0.1" />
        </inertial>
        <visual>
            <origin rpy="0 0 0" xyz="0 0 0" />
            <geometry>
                <mesh filename="package://single_arm_description/meshes/Base.STL" />
            </geometry>
            <material name="">
                <color rgba="0.792156862745098 0.819607843137255 0.933333333333333 1" />
            </material>
        </visual>
        <collision>
            <origin rpy="0 0 0" xyz="0 0 0" />
            <geometry>
                <mesh filename="package://single_arm_description/meshes/Base.STL" />
            </geometry>
        </collision>
    </link>
    <joint name="r_fixed" type="fixed">
        <origin rpy="1.57 3.1415926 3.1415926" xyz="0.0 0.1151 0.0" />
        <parent link="slide_right" />
        <child link="r_Base" />
    </joint>
    <link name="r_Link_1">
        <inertial>
            <origin rpy="0 0 0" xyz="-3.64540734812575E-06 0.00119778550610652 -0.000421399675048756" />
            <mass value="0.386131223153925" />
            <inertia ixx="0.1" ixy="0.0" ixz="0.0" iyy="0.1" iyz="0.0" izz="0.1" />
        </inertial>
        <visual>
            <origin rpy="0 0 0" xyz="0 0 0" />
            <geometry>
                <mesh filename="package://single_arm_description/meshes/Link_1.STL" />
            </geometry>
            <material name="">
                <color rgba="0.898039215686275 0.917647058823529 0.929411764705882 1" />
            </material>
        </visual>
        <collision>
            <origin rpy="0 0 0" xyz="0 0 0" />
            <geometry>
                <mesh filename="package://single_arm_description/meshes/Link_1.STL" />
            </geometry>
        </collision>
    </link>
    <joint name="r_joint_1" type="revolute">
        <origin rpy="-1.5707963267949 -2.60398896659329E-32 1.5707963267949" xyz="0 0 0.0550000000000002" />
        <parent link="r_Base" />
        <child link="r_Link_1" />
        <axis xyz="0 -1 0" />
        <limit effort="1000" lower="-3.14" upper="3.14" velocity="6.5" />
        <dynamics damping="0.7" />
    </joint>
    <link name="r_Link_2">
        <inertial>
            <origin rpy="0 0 0" xyz="0.000683310419598862 -8.00535195483731E-05 0.117541995924546" />
            <mass value="0.479430893999342" />
            <inertia ixx="0.1" ixy="0.0" ixz="0.0" iyy="0.1" iyz="0.0" izz="0.1" />
        </inertial>
        <visual>
            <origin rpy="0 0 0" xyz="0 0 0" />
            <geometry>
                <mesh filename="package://single_arm_description/meshes/Link_2.STL" />
            </geometry>
            <material name="">
                <color rgba="0.898039215686275 0.917647058823529 0.929411764705882 1" />
            </material>
        </visual>
        <collision>
            <origin rpy="0 0 0" xyz="0 0 0" />
            <geometry>
                <mesh filename="package://single_arm_description/meshes/Link_2.STL" />
            </geometry>
        </collision>
    </link>
    <joint name="r_joint_2" type="revolute">
        <origin rpy="-1.5707963267949 7.39557098644699E-32 -1.5707963267949" xyz="0 0 0" />
        <parent link="r_Link_1" />
        <child link="r_Link_2" />
        <axis xyz="0 -1 0" />
        <limit effort="1000" lower="-3.14" upper="3.14" velocity="6.5" />
        <dynamics damping="0.7" />
    </joint>
    <link name="r_Link_3">
        <inertial>
            <origin rpy="0 0 0" xyz="-0.0220564838621471 0.101455973505417 -8.62457453022769E-05" />
            <mass value="0.568306813792926" />
            <inertia ixx="0.1" ixy="0.0" ixz="0.0" iyy="0.1" iyz="0.0" izz="0.1" />
        </inertial>
        <visual>
            <origin rpy="0 0 0" xyz="0 0 0" />
            <geometry>
                <mesh filename="package://single_arm_description/meshes/Link_3.STL" />
            </geometry>
            <material name="">
                <color rgba="0.898039215686275 0.917647058823529 0.929411764705882 1" />
            </material>
        </visual>
        <collision>
            <origin rpy="0 0 0" xyz="0 0 0" />
            <geometry>
                <mesh filename="package://single_arm_description/meshes/Link_3.STL" />
            </geometry>
        </collision>
    </link>
    <joint name="r_joint_3" type="revolute">
        <origin rpy="1.5707963267949 4.63843178081015E-17 6.91111242388425E-16" xyz="0 0 0.174" />
        <parent link="r_Link_2" />
        <child link="r_Link_3" />
        <axis xyz="0 1 0" />
        <limit effort="1000" lower="-3.14" upper="3.14" velocity="6.5" />
        <dynamics damping="0.7" />
    </joint>
    <link name="r_Link_4">
        <inertial>
            <origin rpy="0 0 0" xyz="0.0297389855299131 0.0361651889050357 0.108377256276242" />
            <mass value="0.457613402476782" />
            <inertia ixx="0.1" ixy="0.0" ixz="0.0" iyy="0.1" iyz="0.0" izz="0.1" />
        </inertial>
        <visual>
            <origin rpy="0 0 0" xyz="0 0 0" />
            <geometry>
                <mesh filename="package://single_arm_description/meshes/Link_4.STL" />
            </geometry>
            <material name="">
                <color rgba="0.898039215686275 0.917647058823529 0.929411764705882 1" />
            </material>
        </visual>
        <collision>
            <origin rpy="0 0 0" xyz="0 0 0" />
            <geometry>
                <mesh filename="package://single_arm_description/meshes/Link_4.STL" />
            </geometry>
        </collision>
    </link>
    <joint name="r_joint_4" type="revolute">
        <origin rpy="-1.5707963267949 -1.40443212615082E-14 1.75438367537121E-15" xyz="-0.0299999998727122 0.115999993001519 0.0359999999999999" />
        <parent link="r_Link_3" />
        <child link="r_Link_4" />
        <axis xyz="0 -1 0" />
        <limit effort="1000" lower="-3.14" upper="3.14" velocity="6.5" />
        <dynamics damping="0.7" />
    </joint>
    <link name="r_Link_5">
        <inertial>
            <origin rpy="0 0 0" xyz="-0.000172095429412281 0.102690028206534 -6.66794215013755E-05" />
            <mass value="0.448277275798768" />
            <inertia ixx="0.1" ixy="0.0" ixz="0.0" iyy="0.1" iyz="0.0" izz="0.1" />
        </inertial>
        <visual>
            <origin rpy="0 0 0" xyz="0 0 0" />
            <geometry>
                <mesh filename="package://single_arm_description/meshes/Link_5.STL" />
            </geometry>
            <material name="">
                <color rgba="0.792156862745098 0.819607843137255 0.933333333333333 1" />
            </material>
        </visual>
        <collision>
            <origin rpy="0 0 0" xyz="0 0 0" />
            <geometry>
                <mesh filename="package://single_arm_description/meshes/Link_5.STL" />
            </geometry>
        </collision>
    </link>
    <joint name="r_joint_5" type="revolute">
        <origin rpy="1.5707963267949 -8.80083043478898E-16 -2.49800180540655E-16" xyz="0.029999999872713 0.0359999999999987 0.162" />
        <parent link="r_Link_4" />
        <child link="r_Link_5" />
        <axis xyz="0 1 0" />
        <limit effort="1000" lower="-3.14" upper="3.14" velocity="6.5" />
        <dynamics damping="0.7" />
    </joint>
    <link name="r_Link_6">
        <inertial>
            <origin rpy="0 0 0" xyz="1.14707347786958E-08 0.0359051244401507 0.076720238383497" />
            <mass value="0.205818407044008" />
            <inertia ixx="0.1" ixy="0.0" ixz="0.0" iyy="0.1" iyz="0.0" izz="0.1" />
        </inertial>
        <visual>
            <origin rpy="0 0 0" xyz="0 0 0" />
            <geometry>
                <mesh filename="package://single_arm_description/meshes/Link_6.STL" />
            </geometry>
            <material name="">
                <color rgba="0.898039215686275 0.917647058823529 0.929411764705882 1" />
            </material>
        </visual>
        <collision>
            <origin rpy="0 0 0" xyz="0 0 0" />
            <geometry>
                <mesh filename="package://single_arm_description/meshes/Link_6.STL" />
            </geometry>
        </collision>
    </link>
    <joint name="r_joint_6" type="revolute">
        <origin rpy="-1.5707963267949 0 4.46815747097797E-32" xyz="0 0.108000511190835 0.0360000000000014" />
        <parent link="r_Link_5" />
        <child link="r_Link_6" />
        <axis xyz="0 -1 0" />
        <limit effort="1000" lower="-3.14" upper="3.14" velocity="6.5" />
        <dynamics damping="0.7" />
    </joint>
    <!-- <link
	    name="${side}_Link_7">
	    <inertial>
	      <origin
		xyz="-0.00300603996967419 -5.54762008899146E-05 0.256296304324454"
		rpy="0 0 0" />
	      <mass
		value="0.0968605125725848" />
	      <inertia
		ixx="0.000598660550174727"
		ixy="1.6879862442818E-08"
		ixz="-2.31313376077572E-05"
		iyy="0.000605976408521062"
		iyz="1.75519608508907E-07"
		izz="2.73730335090959E-05" />
	    </inertial>
	    <visual>
	      <origin
		xyz="0 0 0"
		rpy="0 0 0" />
	      <geometry>
		<mesh
		  filename="package://single_arm_description/meshes/Link_7.STL" />
	      </geometry>
	      <material
		name="">
		<color
		  rgba="1 1 1 1" />
	      </material>
	    </visual>
	    <collision>
	      <origin
		xyz="0 0 0"
		rpy="0 0 0" />
	      <geometry>
		<mesh
		  filename="package://single_arm_description/meshes/Link_7.STL" />
	      </geometry>
	    </collision>
	  </link> -->
    <joint name="r_joint_7" type="revolute">
        <origin rpy="0 0 -1.57" xyz="0 0.03680 0.135" />
        <!-- rpy="1.5708 ${toolrot} 0" /> -->
        <!-- xyz="-0.008041 0.038 0.13545" -->
        <!-- xyz="-0.0025 0.038 0.135" -->
        <parent link="r_Link_6" />
        <child link="r_tool_link" />
        <axis xyz="0 0 1" />
        <limit effort="1000" lower="-3.14" upper="3.14" velocity="6.5" />
        <dynamics damping="0.7" />
    </joint>
    <!--
	  <link
	    name="${side}_Link_8">
	    <inertial>
	      <origin
		xyz="9.57945038487507E-05 -0.00931752529150576 -0.00542544640949998"
		rpy="0 0 0" />
	      <mass
		value="0.0130047980464835" />
	      <inertia
		ixx="2.46491406196035E-06"
		ixy="2.73921418079654E-09"
		ixz="-1.30294079932031E-08"
		iyy="1.47440149396087E-06"
		iyz="6.68439506061302E-07"
		izz="2.1558209563788E-06" />
	    </inertial>
	    <visual>
	      <origin
		xyz="0 0 0"
		rpy="0 0 0" />
	      <geometry>
		<mesh
		  filename="package://single_arm_description/meshes/Link_8.STL" />
	      </geometry>
	      <material
		name="">
		<color
		  rgba="0.792156862745098 0.819607843137255 0.933333333333333 1" />
	      </material>
	    </visual>
	    <collision>
	      <origin
		xyz="0 0 0"
		rpy="0 0 0" />
	      <geometry>
		<mesh
		  filename="package://single_arm_description/meshes/Link_8.STL" />
	      </geometry>
	    </collision>
	  </link>
	  <joint
	    name="${side}_joint_8"
	    type="revolute">
	    <origin
	      xyz="0 0 0.3985"
	      rpy="-1.5708 0 0" />
	    <parent
	      link="${side}_Link_7" />
	    <child
	      link="${side}_Link_8" />
	    <axis
	      xyz="0 0 -1" />
	    <limit
	      lower="-3.14"
	      upper="3.14"
	      effort="2"
	      velocity="2" />
	  </joint>
	-->
    <transmission name="r_tran1">
        <type>transmission_interface/SimpleTransmission</type>
        <joint name="r_joint_1">
            <hardwareInterface>hardware_interface/EffortJointInterface</hardwareInterface>
        </joint>
        <actuator name="r_motor1">
            <hardwareInterface>hardware_interface/EffortJointInterface</hardwareInterface>
            <mechanicalReduction>1</mechanicalReduction>
        </actuator>
    </transmission>
    <transmission name="r_tran2">
        <type>transmission_interface/SimpleTransmission</type>
        <joint name="r_joint_2">
            <hardwareInterface>hardware_interface/EffortJointInterface</hardwareInterface>
        </joint>
        <actuator name="r_motor2">
            <hardwareInterface>hardware_interface/EffortJointInterface</hardwareInterface>
            <mechanicalReduction>1</mechanicalReduction>
        </actuator>
    </transmission>
    <transmission name="r_tran3">
        <type>transmission_interface/SimpleTransmission</type>
        <joint name="r_joint_3">
            <hardwareInterface>hardware_interface/EffortJointInterface</hardwareInterface>
        </joint>
        <actuator name="r_motor3">
            <hardwareInterface>hardware_interface/EffortJointInterface</hardwareInterface>
            <mechanicalReduction>1</mechanicalReduction>
        </actuator>
    </transmission>
    <transmission name="r_tran4">
        <type>transmission_interface/SimpleTransmission</type>
        <joint name="r_joint_4">
            <hardwareInterface>hardware_interface/EffortJointInterface</hardwareInterface>
        </joint>
        <actuator name="r_motor4">
            <hardwareInterface>hardware_interface/EffortJointInterface</hardwareInterface>
            <mechanicalReduction>1</mechanicalReduction>
        </actuator>
    </transmission>
    <transmission name="r_tran5">
        <type>transmission_interface/SimpleTransmission</type>
        <joint name="r_joint_5">
            <hardwareInterface>hardware_interface/EffortJointInterface</hardwareInterface>
        </joint>
        <actuator name="r_motor5">
            <hardwareInterface>hardware_interface/EffortJointInterface</hardwareInterface>
            <mechanicalReduction>1</mechanicalReduction>
        </actuator>
    </transmission>
    <transmission name="r_tran6">
        <type>transmission_interface/SimpleTransmission</type>
        <joint name="r_joint_6">
            <hardwareInterface>hardware_interface/EffortJointInterface</hardwareInterface>
        </joint>
        <actuator name="r_motor6">
            <hardwareInterface>hardware_interface/EffortJointInterface</hardwareInterface>
            <mechanicalReduction>1</mechanicalReduction>
        </actuator>
    </transmission>
    <transmission name="r_tran7">
        <type>transmission_interface/SimpleTransmission</type>
        <joint name="r_joint_7">
            <hardwareInterface>hardware_interface/EffortJointInterface</hardwareInterface>
        </joint>
        <actuator name="r_motor7">
            <hardwareInterface>hardware_interface/EffortJointInterface</hardwareInterface>
            <mechanicalReduction>1</mechanicalReduction>
        </actuator>
    </transmission>
    <!-- Link1 -->
    <gazebo reference="r_Base">
        <mu1>0.2</mu1>
        <mu2>0.2</mu2>
        <material>Gazebo/Orange</material>
        <selfCollide>false</selfCollide>
    </gazebo>
    <!-- Link2 -->
    <gazebo reference="r_Link_1">
        <mu1>0.2</mu1>
        <mu2>0.2</mu2>
        <material>Gazebo/Black</material>
        <selfCollide>false</selfCollide>
    </gazebo>
    <!-- Link3 -->
    <gazebo reference="r_Link_2">
        <mu1>0.2</mu1>
        <mu2>0.2</mu2>
        <material>Gazebo/Orange</material>
        <selfCollide>false</selfCollide>
    </gazebo>
    <gazebo reference="r_Link_3">
        <mu1>0.2</mu1>
        <mu2>0.2</mu2>
        <material>Gazebo/Black</material>
        <selfCollide>false</selfCollide>
    </gazebo>
    <gazebo reference="r_Link_4">
        <mu1>0.2</mu1>
        <mu2>0.2</mu2>
        <material>Gazebo/Orange</material>
        <selfCollide>false</selfCollide>
    </gazebo>
    <gazebo reference="r_Link_5">
        <mu1>0.2</mu1>
        <mu2>0.2</mu2>
        <material>Gazebo/Black</material>
        <selfCollide>false</selfCollide>
    </gazebo>
    <gazebo reference="r_Link_6">
        <mu1>0.2</mu1>
        <mu2>0.2</mu2>
        <material>Gazebo/Orange</material>
        <selfCollide>false</selfCollide>
    </gazebo>
    <gazebo reference="r_joint_1">
        <implicitSpringDamper>True</implicitSpringDamper>
    </gazebo>
    <gazebo reference="r_joint_2">
        <implicitSpringDamper>True</implicitSpringDamper>
    </gazebo>
    <gazebo reference="r_joint_3">
        <implicitSpringDamper>True</implicitSpringDamper>
    </gazebo>
    <gazebo reference="r_joint_4">
        <implicitSpringDamper>True</implicitSpringDamper>
    </gazebo>
    <gazebo reference="r_joint_5">
        <implicitSpringDamper>True</implicitSpringDamper>
    </gazebo>
    <gazebo reference="r_joint_6">
        <implicitSpringDamper>True</implicitSpringDamper>
    </gazebo>
    <gazebo reference="r_joint_7">
        <implicitSpringDamper>True</implicitSpringDamper>
    </gazebo>
    <!-- <gazebo reference="${side}_Link_7">
    <mu1>0.2</mu1>
    <mu2>0.2</mu2>
    <material>Gazebo/Black</material>
    <selfCollide>false</selfCollide>
  </gazebo> -->
    <!--
  <gazebo reference="${side}_Link_8">
    <mu1>0.2</mu1>
    <mu2>0.2</mu2>
    <material>Gazebo/Orange</material>
    <selfCollide>false</selfCollide>
  </gazebo>
  -->
    <link name="r_tool_link">
        <inertial>
            <origin rpy="0 0 0" xyz="-0.003041 0.0027723 0.043545" />
            <mass value="0.11123" />
            <inertia ixx="0.1" ixy="0.0" ixz="0.0" iyy="0.1" iyz="0.0" izz="0.1" />
        </inertial>
        <visual>
            <origin rpy="0 0 0" xyz="0 0 0" />
            <geometry>
                <mesh filename="package://suction_urdf/meshes/tool_link.STL" />
            </geometry>
            <material name="">
                <color rgba="1 1 1 1" />
            </material>
        </visual>
        <collision>
            <origin rpy="0 0 0" xyz="0 0 0" />
            <geometry>
                <mesh filename="package://suction_urdf/meshes/tool_link.STL" />
            </geometry>
        </collision>
    </link>
    <link name="r_tool_end_Link">
        <inertial>
            <origin rpy="0 0 0" xyz="9.909E-05 0.0039906 0.025651" />
            <mass value="0.033438" />
            <inertia ixx="0.1" ixy="0.0" ixz="0.0" iyy="0.1" iyz="0.0" izz="0.1" />
        </inertial>
        <visual>
            <origin rpy="0 0 0" xyz="0 0 0" />
            <geometry>
                <mesh filename="package://suction_urdf/meshes/tool_end_Link.STL" />
            </geometry>
            <material name="">
                <color rgba="0.79216 0.81961 0.93333 1" />
            </material>
        </visual>
        <collision>
            <origin rpy="0 0 0" xyz="0 0 0" />
            <geometry>
                <mesh filename="package://suction_urdf/meshes/tool_end_Link.STL" />
            </geometry>
        </collision>
    </link>
    <joint name="r_tool_joint" type="revolute">
        <origin rpy="-1.7985E-15 -2.9973E-16 1.1669E-16" xyz="0 0.002 0.1045" />
        <parent link="r_tool_link" />
        <child link="r_tool_end_Link" />
        <axis xyz="0 1 0" />
        <limit effort="1000" lower="-3.14" upper="3.14" velocity="6.5" />
        <dynamics damping="0.7" />
    </joint>
    <link name="r_end_Link1">
        <gravity>0</gravity>
        <inertial>
            <origin rpy="0 0 0" xyz="0 0 0" />
            <mass value="0.0001" />
            <inertia ixx="0.0001" ixy="0.000" ixz="0.000" iyy="0.0001" iyz="0.000" izz="0.0001" />
        </inertial>
        <visual>
            <origin rpy="0 0 0" xyz="0 0 0" />
            <geometry>
                <box size="0.01 0.01 0.01" />
            </geometry>
            <material name="transparent">
                <color rgba="0 0 0 0" />
            </material>
        </visual>
    </link>
    <joint name="r_end_joint1" type="revolute">
        <origin rpy="0 1.5708 0" xyz="0 -0.001 0.06" />
        <parent link="r_tool_end_Link" />
        <child link="r_end_Link1" />
        <axis xyz="1 0 0" />
        <limit effort="1000" lower="0" upper="0" velocity="6.5" />
        <dynamics damping="0.0" friction="10" />
    </joint>
    <link name="r_end_Link2">
        <gravity>0</gravity>
        <inertial>
            <origin rpy="0 0 0" xyz="0 0 0" />
            <mass value="0.0001" />
            <inertia ixx="0.0001" ixy="0.000" ixz="0.000" iyy="0.0001" iyz="0.000" izz="0.0001" />
        </inertial>
        <visual>
            <origin rpy="0 0 0" xyz="0 0 0" />
            <geometry>
                <box size="0.01 0.01 0.01" />
            </geometry>
            <material name="transparent">
                <color rgba="0 0 0 0" />
            </material>
        </visual>
    </link>
    <joint name="r_end_joint2" type="revolute">
        <origin rpy="0 1.5708 0" xyz="-0.0125 -0.001 0.06" />
        <parent link="r_tool_end_Link" />
        <child link="r_end_Link2" />
        <axis xyz="1 0 0" />
        <limit effort="1000" lower="0" upper="0" velocity="6.5" />
        <dynamics damping="0.0" friction="10" />
    </joint>
    <link name="r_end_Link3">
        <gravity>0</gravity>
        <inertial>
            <origin rpy="0 0 0" xyz="0 0 0" />
            <mass value="0.0001" />
            <inertia ixx="0.0001" ixy="0.000" ixz="0.000" iyy="0.0001" iyz="0.000" izz="0.0001" />
        </inertial>
        <visual>
            <origin rpy="0 0 0" xyz="0 0 0" />
            <geometry>
                <box size="0.01 0.01 0.01" />
            </geometry>
            <material name="transparent">
                <color rgba="0 0 0 0" />
            </material>
        </visual>
    </link>
    <joint name="r_end_joint3" type="revolute">
        <origin rpy="0 1.5708 0" xyz="0.0125 -0.001 0.06" />
        <parent link="r_tool_end_Link" />
        <child link="r_end_Link3" />
        <axis xyz="1 0 0" />
        <limit effort="1000" lower="0" upper="0" velocity="6.5" />
        <dynamics damping="0.0" friction="10" />
    </joint>
    <link name="r_end_Link4">
        <gravity>0</gravity>
        <inertial>
            <origin rpy="0 0 0" xyz="0 0 0" />
            <mass value="0.0001" />
            <inertia ixx="0.0001" ixy="0.000" ixz="0.000" iyy="0.0001" iyz="0.000" izz="0.0001" />
        </inertial>
        <visual>
            <origin rpy="0 0 0" xyz="0 0 0" />
            <geometry>
                <box size="0.01 0.01 0.01" />
            </geometry>
            <material name="transparent">
                <color rgba="0 0 0 0" />
            </material>
        </visual>
    </link>
    <joint name="r_end_joint4" type="revolute">
        <origin rpy="0 1.5708 0" xyz="0 -0.001 0.0475" />
        <parent link="r_tool_end_Link" />
        <child link="r_end_Link4" />
        <axis xyz="1 0 0" />
        <limit effort="1000" lower="0" upper="0" velocity="6.5" />
        <dynamics damping="0.0" friction="10" />
    </joint>
    <link name="r_end_Link5">
        <gravity>0</gravity>
        <inertial>
            <origin rpy="0 0 0" xyz="0 0 0" />
            <mass value="0.0001" />
            <inertia ixx="0.0001" ixy="0.000" ixz="0.000" iyy="0.0001" iyz="0.000" izz="0.0001" />
        </inertial>
        <visual>
            <origin rpy="0 0 0" xyz="0 0 0" />
            <geometry>
                <box size="0.01 0.01 0.01" />
            </geometry>
            <material name="transparent">
                <color rgba="0 0 0 0" />
            </material>
        </visual>
    </link>
    <joint name="r_end_joint5" type="revolute">
        <origin rpy="0 1.5708 0" xyz="0 -0.001 0.0725" />
        <parent link="r_tool_end_Link" />
        <child link="r_end_Link5" />
        <axis xyz="1 0 0" />
        <limit effort="1000" lower="0" upper="0" velocity="6.5" />
        <dynamics damping="0.0" friction="10" />
    </joint>
    <transmission name="r_suction_tran">
        <type>transmission_interface/SimpleTransmission</type>
        <joint name="r_tool_joint">
            <hardwareInterface>hardware_interface/EffortJointInterface</hardwareInterface>
        </joint>
        <actuator name="r_suction_motor1">
            <hardwareInterface>hardware_interface/EffortJointInterface</hardwareInterface>
            <mechanicalReduction>1</mechanicalReduction>
        </actuator>
    </transmission>
    <!-- Link1 -->
    <gazebo reference="r_tool_link">
        <mu1>0.2</mu1>
        <mu2>0.2</mu2>
        <material>Gazebo/white</material>
        <selfCollide>false</selfCollide>
    </gazebo>
    <gazebo reference="r_tool_end_Link">
        <mu1>0.2</mu1>
        <mu2>0.2</mu2>
        <material>Gazebo/grey</material>
        <selfCollide>false</selfCollide>
    </gazebo>
    <link name="l_Base">
        <inertial>
            <origin rpy="0 0 0" xyz="0.000156250860732315 0.000202963757501797 -0.0546720420122521" />
            <mass value="0.323603974032196" />
            <inertia ixx="0.1" ixy="0.0" ixz="0.0" iyy="0.1" iyz="0.0" izz="0.1" />
        </inertial>
        <visual>
            <origin rpy="0 0 0" xyz="0 0 0" />
            <geometry>
                <mesh filename="package://single_arm_description/meshes/Base.STL" />
            </geometry>
            <material name="">
                <color rgba="0.792156862745098 0.819607843137255 0.933333333333333 1" />
            </material>
        </visual>
        <collision>
            <origin rpy="0 0 0" xyz="0 0 0" />
            <geometry>
                <mesh filename="package://single_arm_description/meshes/Base.STL" />
            </geometry>
        </collision>
    </link>
    <joint name="l_fixed" type="fixed">
        <origin rpy="-1.57 0 0" xyz="0.0 0.1151 0.0" />
        <parent link="slide_left" />
        <child link="l_Base" />
    </joint>
    <link name="l_Link_1">
        <inertial>
            <origin rpy="0 0 0" xyz="-3.64540734812575E-06 0.00119778550610652 -0.000421399675048756" />
            <mass value="0.386131223153925" />
            <inertia ixx="0.1" ixy="0.0" ixz="0.0" iyy="0.1" iyz="0.0" izz="0.1" />
        </inertial>
        <visual>
            <origin rpy="0 0 0" xyz="0 0 0" />
            <geometry>
                <mesh filename="package://single_arm_description/meshes/Link_1.STL" />
            </geometry>
            <material name="">
                <color rgba="0.898039215686275 0.917647058823529 0.929411764705882 1" />
            </material>
        </visual>
        <collision>
            <origin rpy="0 0 0" xyz="0 0 0" />
            <geometry>
                <mesh filename="package://single_arm_description/meshes/Link_1.STL" />
            </geometry>
        </collision>
    </link>
    <joint name="l_joint_1" type="revolute">
        <origin rpy="-1.5707963267949 -2.60398896659329E-32 1.5707963267949" xyz="0 0 0.0550000000000002" />
        <parent link="l_Base" />
        <child link="l_Link_1" />
        <axis xyz="0 -1 0" />
        <limit effort="1000" lower="-3.14" upper="3.14" velocity="6.5" />
        <dynamics damping="0.7" />
    </joint>
    <link name="l_Link_2">
        <inertial>
            <origin rpy="0 0 0" xyz="0.000683310419598862 -8.00535195483731E-05 0.117541995924546" />
            <mass value="0.479430893999342" />
            <inertia ixx="0.1" ixy="0.0" ixz="0.0" iyy="0.1" iyz="0.0" izz="0.1" />
        </inertial>
        <visual>
            <origin rpy="0 0 0" xyz="0 0 0" />
            <geometry>
                <mesh filename="package://single_arm_description/meshes/Link_2.STL" />
            </geometry>
            <material name="">
                <color rgba="0.898039215686275 0.917647058823529 0.929411764705882 1" />
            </material>
        </visual>
        <collision>
            <origin rpy="0 0 0" xyz="0 0 0" />
            <geometry>
                <mesh filename="package://single_arm_description/meshes/Link_2.STL" />
            </geometry>
        </collision>
    </link>
    <joint name="l_joint_2" type="revolute">
        <origin rpy="-1.5707963267949 7.39557098644699E-32 -1.5707963267949" xyz="0 0 0" />
        <parent link="l_Link_1" />
        <child link="l_Link_2" />
        <axis xyz="0 -1 0" />
        <limit effort="1000" lower="-3.14" upper="3.14" velocity="6.5" />
        <dynamics damping="0.7" />
    </joint>
    <link name="l_Link_3">
        <inertial>
            <origin rpy="0 0 0" xyz="-0.0220564838621471 0.101455973505417 -8.62457453022769E-05" />
            <mass value="0.568306813792926" />
            <inertia ixx="0.1" ixy="0.0" ixz="0.0" iyy="0.1" iyz="0.0" izz="0.1" />
        </inertial>
        <visual>
            <origin rpy="0 0 0" xyz="0 0 0" />
            <geometry>
                <mesh filename="package://single_arm_description/meshes/Link_3.STL" />
            </geometry>
            <material name="">
                <color rgba="0.898039215686275 0.917647058823529 0.929411764705882 1" />
            </material>
        </visual>
        <collision>
            <origin rpy="0 0 0" xyz="0 0 0" />
            <geometry>
                <mesh filename="package://single_arm_description/meshes/Link_3.STL" />
            </geometry>
        </collision>
    </link>
    <joint name="l_joint_3" type="revolute">
        <origin rpy="1.5707963267949 4.63843178081015E-17 6.91111242388425E-16" xyz="0 0 0.174" />
        <parent link="l_Link_2" />
        <child link="l_Link_3" />
        <axis xyz="0 1 0" />
        <limit effort="1000" lower="-3.14" upper="3.14" velocity="6.5" />
        <dynamics damping="0.7" />
    </joint>
    <link name="l_Link_4">
        <inertial>
            <origin rpy="0 0 0" xyz="0.0297389855299131 0.0361651889050357 0.108377256276242" />
            <mass value="0.457613402476782" />
            <inertia ixx="0.1" ixy="0.0" ixz="0.0" iyy="0.1" iyz="0.0" izz="0.1" />
        </inertial>
        <visual>
            <origin rpy="0 0 0" xyz="0 0 0" />
            <geometry>
                <mesh filename="package://single_arm_description/meshes/Link_4.STL" />
            </geometry>
            <material name="">
                <color rgba="0.898039215686275 0.917647058823529 0.929411764705882 1" />
            </material>
        </visual>
        <collision>
            <origin rpy="0 0 0" xyz="0 0 0" />
            <geometry>
                <mesh filename="package://single_arm_description/meshes/Link_4.STL" />
            </geometry>
        </collision>
    </link>
    <joint name="l_joint_4" type="revolute">
        <origin rpy="-1.5707963267949 -1.40443212615082E-14 1.75438367537121E-15" xyz="-0.0299999998727122 0.115999993001519 0.0359999999999999" />
        <parent link="l_Link_3" />
        <child link="l_Link_4" />
        <axis xyz="0 -1 0" />
        <limit effort="1000" lower="-3.14" upper="3.14" velocity="6.5" />
        <dynamics damping="0.7" />
    </joint>
    <link name="l_Link_5">
        <inertial>
            <origin rpy="0 0 0" xyz="-0.000172095429412281 0.102690028206534 -6.66794215013755E-05" />
            <mass value="0.448277275798768" />
            <inertia ixx="0.1" ixy="0.0" ixz="0.0" iyy="0.1" iyz="0.0" izz="0.1" />
        </inertial>
        <visual>
            <origin rpy="0 0 0" xyz="0 0 0" />
            <geometry>
                <mesh filename="package://single_arm_description/meshes/Link_5.STL" />
            </geometry>
            <material name="">
                <color rgba="0.792156862745098 0.819607843137255 0.933333333333333 1" />
            </material>
        </visual>
        <collision>
            <origin rpy="0 0 0" xyz="0 0 0" />
            <geometry>
                <mesh filename="package://single_arm_description/meshes/Link_5.STL" />
            </geometry>
        </collision>
    </link>
    <joint name="l_joint_5" type="revolute">
        <origin rpy="1.5707963267949 -8.80083043478898E-16 -2.49800180540655E-16" xyz="0.029999999872713 0.0359999999999987 0.162" />
        <parent link="l_Link_4" />
        <child link="l_Link_5" />
        <axis xyz="0 1 0" />
        <limit effort="1000" lower="-3.14" upper="3.14" velocity="6.5" />
        <dynamics damping="0.7" />
    </joint>
    <link name="l_Link_6">
        <inertial>
            <origin rpy="0 0 0" xyz="1.14707347786958E-08 0.0359051244401507 0.076720238383497" />
            <mass value="0.205818407044008" />
            <inertia ixx="0.1" ixy="0.0" ixz="0.0" iyy="0.1" iyz="0.0" izz="0.1" />
        </inertial>
        <visual>
            <origin rpy="0 0 0" xyz="0 0 0" />
            <geometry>
                <mesh filename="package://single_arm_description/meshes/Link_6.STL" />
            </geometry>
            <material name="">
                <color rgba="0.898039215686275 0.917647058823529 0.929411764705882 1" />
            </material>
        </visual>
        <collision>
            <origin rpy="0 0 0" xyz="0 0 0" />
            <geometry>
                <mesh filename="package://single_arm_description/meshes/Link_6.STL" />
            </geometry>
        </collision>
    </link>
    <joint name="l_joint_6" type="revolute">
        <origin rpy="-1.5707963267949 0 4.46815747097797E-32" xyz="0 0.108000511190835 0.0360000000000014" />
        <parent link="l_Link_5" />
        <child link="l_Link_6" />
        <axis xyz="0 -1 0" />
        <limit effort="1000" lower="-3.14" upper="3.14" velocity="6.5" />
        <dynamics damping="0.7" />
    </joint>
    <!-- <link
	    name="${side}_Link_7">
	    <inertial>
	      <origin
		xyz="-0.00300603996967419 -5.54762008899146E-05 0.256296304324454"
		rpy="0 0 0" />
	      <mass
		value="0.0968605125725848" />
	      <inertia
		ixx="0.000598660550174727"
		ixy="1.6879862442818E-08"
		ixz="-2.31313376077572E-05"
		iyy="0.000605976408521062"
		iyz="1.75519608508907E-07"
		izz="2.73730335090959E-05" />
	    </inertial>
	    <visual>
	      <origin
		xyz="0 0 0"
		rpy="0 0 0" />
	      <geometry>
		<mesh
		  filename="package://single_arm_description/meshes/Link_7.STL" />
	      </geometry>
	      <material
		name="">
		<color
		  rgba="1 1 1 1" />
	      </material>
	    </visual>
	    <collision>
	      <origin
		xyz="0 0 0"
		rpy="0 0 0" />
	      <geometry>
		<mesh
		  filename="package://single_arm_description/meshes/Link_7.STL" />
	      </geometry>
	    </collision>
	  </link> -->
    <joint name="l_joint_7" type="revolute">
        <origin rpy="0 0 1.57" xyz="0 0.03680 0.135" />
        <!-- rpy="1.5708 ${toolrot} 0" /> -->
        <!-- xyz="-0.008041 0.038 0.13545" -->
        <!-- xyz="-0.0025 0.038 0.135" -->
        <parent link="l_Link_6" />
        <child link="l_tool_link" />
        <axis xyz="0 0 1" />
        <limit effort="1000" lower="-3.14" upper="3.14" velocity="6.5" />
        <dynamics damping="0.7" />
    </joint>
    <!--
	  <link
	    name="${side}_Link_8">
	    <inertial>
	      <origin
		xyz="9.57945038487507E-05 -0.00931752529150576 -0.00542544640949998"
		rpy="0 0 0" />
	      <mass
		value="0.0130047980464835" />
	      <inertia
		ixx="2.46491406196035E-06"
		ixy="2.73921418079654E-09"
		ixz="-1.30294079932031E-08"
		iyy="1.47440149396087E-06"
		iyz="6.68439506061302E-07"
		izz="2.1558209563788E-06" />
	    </inertial>
	    <visual>
	      <origin
		xyz="0 0 0"
		rpy="0 0 0" />
	      <geometry>
		<mesh
		  filename="package://single_arm_description/meshes/Link_8.STL" />
	      </geometry>
	      <material
		name="">
		<color
		  rgba="0.792156862745098 0.819607843137255 0.933333333333333 1" />
	      </material>
	    </visual>
	    <collision>
	      <origin
		xyz="0 0 0"
		rpy="0 0 0" />
	      <geometry>
		<mesh
		  filename="package://single_arm_description/meshes/Link_8.STL" />
	      </geometry>
	    </collision>
	  </link>
	  <joint
	    name="${side}_joint_8"
	    type="revolute">
	    <origin
	      xyz="0 0 0.3985"
	      rpy="-1.5708 0 0" />
	    <parent
	      link="${side}_Link_7" />
	    <child
	      link="${side}_Link_8" />
	    <axis
	      xyz="0 0 -1" />
	    <limit
	      lower="-3.14"
	      upper="3.14"
	      effort="2"
	      velocity="2" />
	  </joint>
	-->
    <transmission name="l_tran1">
        <type>transmission_interface/SimpleTransmission</type>
        <joint name="l_joint_1">
            <hardwareInterface>hardware_interface/EffortJointInterface</hardwareInterface>
        </joint>
        <actuator name="l_motor1">
            <hardwareInterface>hardware_interface/EffortJointInterface</hardwareInterface>
            <mechanicalReduction>1</mechanicalReduction>
        </actuator>
    </transmission>
    <transmission name="l_tran2">
        <type>transmission_interface/SimpleTransmission</type>
        <joint name="l_joint_2">
            <hardwareInterface>hardware_interface/EffortJointInterface</hardwareInterface>
        </joint>
        <actuator name="l_motor2">
            <hardwareInterface>hardware_interface/EffortJointInterface</hardwareInterface>
            <mechanicalReduction>1</mechanicalReduction>
        </actuator>
    </transmission>
    <transmission name="l_tran3">
        <type>transmission_interface/SimpleTransmission</type>
        <joint name="l_joint_3">
            <hardwareInterface>hardware_interface/EffortJointInterface</hardwareInterface>
        </joint>
        <actuator name="l_motor3">
            <hardwareInterface>hardware_interface/EffortJointInterface</hardwareInterface>
            <mechanicalReduction>1</mechanicalReduction>
        </actuator>
    </transmission>
    <transmission name="l_tran4">
        <type>transmission_interface/SimpleTransmission</type>
        <joint name="l_joint_4">
            <hardwareInterface>hardware_interface/EffortJointInterface</hardwareInterface>
        </joint>
        <actuator name="l_motor4">
            <hardwareInterface>hardware_interface/EffortJointInterface</hardwareInterface>
            <mechanicalReduction>1</mechanicalReduction>
        </actuator>
    </transmission>
    <transmission name="l_tran5">
        <type>transmission_interface/SimpleTransmission</type>
        <joint name="l_joint_5">
            <hardwareInterface>hardware_interface/EffortJointInterface</hardwareInterface>
        </joint>
        <actuator name="l_motor5">
            <hardwareInterface>hardware_interface/EffortJointInterface</hardwareInterface>
            <mechanicalReduction>1</mechanicalReduction>
        </actuator>
    </transmission>
    <transmission name="l_tran6">
        <type>transmission_interface/SimpleTransmission</type>
        <joint name="l_joint_6">
            <hardwareInterface>hardware_interface/EffortJointInterface</hardwareInterface>
        </joint>
        <actuator name="l_motor6">
            <hardwareInterface>hardware_interface/EffortJointInterface</hardwareInterface>
            <mechanicalReduction>1</mechanicalReduction>
        </actuator>
    </transmission>
    <transmission name="l_tran7">
        <type>transmission_interface/SimpleTransmission</type>
        <joint name="l_joint_7">
            <hardwareInterface>hardware_interface/EffortJointInterface</hardwareInterface>
        </joint>
        <actuator name="l_motor7">
            <hardwareInterface>hardware_interface/EffortJointInterface</hardwareInterface>
            <mechanicalReduction>1</mechanicalReduction>
        </actuator>
    </transmission>
    <!-- Link1 -->
    <gazebo reference="l_Base">
        <mu1>0.2</mu1>
        <mu2>0.2</mu2>
        <material>Gazebo/Orange</material>
        <selfCollide>false</selfCollide>
    </gazebo>
    <!-- Link2 -->
    <gazebo reference="l_Link_1">
        <mu1>0.2</mu1>
        <mu2>0.2</mu2>
        <material>Gazebo/Black</material>
        <selfCollide>false</selfCollide>
    </gazebo>
    <!-- Link3 -->
    <gazebo reference="l_Link_2">
        <mu1>0.2</mu1>
        <mu2>0.2</mu2>
        <material>Gazebo/Orange</material>
        <selfCollide>false</selfCollide>
    </gazebo>
    <gazebo reference="l_Link_3">
        <mu1>0.2</mu1>
        <mu2>0.2</mu2>
        <material>Gazebo/Black</material>
        <selfCollide>false</selfCollide>
    </gazebo>
    <gazebo reference="l_Link_4">
        <mu1>0.2</mu1>
        <mu2>0.2</mu2>
        <material>Gazebo/Orange</material>
        <selfCollide>false</selfCollide>
    </gazebo>
    <gazebo reference="l_Link_5">
        <mu1>0.2</mu1>
        <mu2>0.2</mu2>
        <material>Gazebo/Black</material>
        <selfCollide>false</selfCollide>
    </gazebo>
    <gazebo reference="l_Link_6">
        <mu1>0.2</mu1>
        <mu2>0.2</mu2>
        <material>Gazebo/Orange</material>
        <selfCollide>false</selfCollide>
    </gazebo>
    <gazebo reference="l_joint_1">
        <implicitSpringDamper>True</implicitSpringDamper>
    </gazebo>
    <gazebo reference="l_joint_2">
        <implicitSpringDamper>True</implicitSpringDamper>
    </gazebo>
    <gazebo reference="l_joint_3">
        <implicitSpringDamper>True</implicitSpringDamper>
    </gazebo>
    <gazebo reference="l_joint_4">
        <implicitSpringDamper>True</implicitSpringDamper>
    </gazebo>
    <gazebo reference="l_joint_5">
        <implicitSpringDamper>True</implicitSpringDamper>
    </gazebo>
    <gazebo reference="l_joint_6">
        <implicitSpringDamper>True</implicitSpringDamper>
    </gazebo>
    <gazebo reference="l_joint_7">
        <implicitSpringDamper>True</implicitSpringDamper>
    </gazebo>
    <!-- <gazebo reference="${side}_Link_7">
    <mu1>0.2</mu1>
    <mu2>0.2</mu2>
    <material>Gazebo/Black</material>
    <selfCollide>false</selfCollide>
  </gazebo> -->
    <!--
  <gazebo reference="${side}_Link_8">
    <mu1>0.2</mu1>
    <mu2>0.2</mu2>
    <material>Gazebo/Orange</material>
    <selfCollide>false</selfCollide>
  </gazebo>
  -->
    <link name="l_tool_link">
        <inertial>
            <origin rpy="0 0 0" xyz="-0.003041 0.0027723 0.043545" />
            <mass value="0.11123" />
            <inertia ixx="0.1" ixy="0.0" ixz="0.0" iyy="0.1" iyz="0.0" izz="0.1" />
        </inertial>
        <visual>
            <origin rpy="0 0 0" xyz="0 0 0" />
            <geometry>
                <mesh filename="package://suction_urdf/meshes/tool_link.STL" />
            </geometry>
            <material name="">
                <color rgba="1 1 1 1" />
            </material>
        </visual>
        <collision>
            <origin rpy="0 0 0" xyz="0 0 0" />
            <geometry>
                <mesh filename="package://suction_urdf/meshes/tool_link.STL" />
            </geometry>
        </collision>
    </link>
    <link name="l_tool_end_Link">
        <inertial>
            <origin rpy="0 0 0" xyz="9.909E-05 0.0039906 0.025651" />
            <mass value="0.033438" />
            <inertia ixx="0.1" ixy="0.0" ixz="0.0" iyy="0.1" iyz="0.0" izz="0.1" />
        </inertial>
        <visual>
            <origin rpy="0 0 0" xyz="0 0 0" />
            <geometry>
                <mesh filename="package://suction_urdf/meshes/tool_end_Link.STL" />
            </geometry>
            <material name="">
                <color rgba="0.79216 0.81961 0.93333 1" />
            </material>
        </visual>
        <collision>
            <origin rpy="0 0 0" xyz="0 0 0" />
            <geometry>
                <mesh filename="package://suction_urdf/meshes/tool_end_Link.STL" />
            </geometry>
        </collision>
    </link>
    <joint name="l_tool_joint" type="revolute">
        <origin rpy="-1.7985E-15 -2.9973E-16 1.1669E-16" xyz="0 0.002 0.1045" />
        <parent link="l_tool_link" />
        <child link="l_tool_end_Link" />
        <axis xyz="0 1 0" />
        <limit effort="1000" lower="-3.14" upper="3.14" velocity="6.5" />
        <dynamics damping="0.7" />
    </joint>
    <link name="l_end_Link1">
        <gravity>0</gravity>
        <inertial>
            <origin rpy="0 0 0" xyz="0 0 0" />
            <mass value="0.0001" />
            <inertia ixx="0.0001" ixy="0.000" ixz="0.000" iyy="0.0001" iyz="0.000" izz="0.0001" />
        </inertial>
        <visual>
            <origin rpy="0 0 0" xyz="0 0 0" />
            <geometry>
                <box size="0.01 0.01 0.01" />
            </geometry>
            <material name="transparent">
                <color rgba="0 0 0 0" />
            </material>
        </visual>
    </link>
    <joint name="l_end_joint1" type="revolute">
        <origin rpy="0 1.5708 0" xyz="0 -0.001 0.06" />
        <parent link="l_tool_end_Link" />
        <child link="l_end_Link1" />
        <axis xyz="1 0 0" />
        <limit effort="1000" lower="0" upper="0" velocity="6.5" />
        <dynamics damping="0.0" friction="10" />
    </joint>
    <link name="l_end_Link2">
        <gravity>0</gravity>
        <inertial>
            <origin rpy="0 0 0" xyz="0 0 0" />
            <mass value="0.0001" />
            <inertia ixx="0.0001" ixy="0.000" ixz="0.000" iyy="0.0001" iyz="0.000" izz="0.0001" />
        </inertial>
        <visual>
            <origin rpy="0 0 0" xyz="0 0 0" />
            <geometry>
                <box size="0.01 0.01 0.01" />
            </geometry>
            <material name="transparent">
                <color rgba="0 0 0 0" />
            </material>
        </visual>
    </link>
    <joint name="l_end_joint2" type="revolute">
        <origin rpy="0 1.5708 0" xyz="-0.0125 -0.001 0.06" />
        <parent link="l_tool_end_Link" />
        <child link="l_end_Link2" />
        <axis xyz="1 0 0" />
        <limit effort="1000" lower="0" upper="0" velocity="6.5" />
        <dynamics damping="0.0" friction="10" />
    </joint>
    <link name="l_end_Link3">
        <gravity>0</gravity>
        <inertial>
            <origin rpy="0 0 0" xyz="0 0 0" />
            <mass value="0.0001" />
            <inertia ixx="0.0001" ixy="0.000" ixz="0.000" iyy="0.0001" iyz="0.000" izz="0.0001" />
        </inertial>
        <visual>
            <origin rpy="0 0 0" xyz="0 0 0" />
            <geometry>
                <box size="0.01 0.01 0.01" />
            </geometry>
            <material name="transparent">
                <color rgba="0 0 0 0" />
            </material>
        </visual>
    </link>
    <joint name="l_end_joint3" type="revolute">
        <origin rpy="0 1.5708 0" xyz="0.0125 -0.001 0.06" />
        <parent link="l_tool_end_Link" />
        <child link="l_end_Link3" />
        <axis xyz="1 0 0" />
        <limit effort="1000" lower="0" upper="0" velocity="6.5" />
        <dynamics damping="0.0" friction="10" />
    </joint>
    <link name="l_end_Link4">
        <gravity>0</gravity>
        <inertial>
            <origin rpy="0 0 0" xyz="0 0 0" />
            <mass value="0.0001" />
            <inertia ixx="0.0001" ixy="0.000" ixz="0.000" iyy="0.0001" iyz="0.000" izz="0.0001" />
        </inertial>
        <visual>
            <origin rpy="0 0 0" xyz="0 0 0" />
            <geometry>
                <box size="0.01 0.01 0.01" />
            </geometry>
            <material name="transparent">
                <color rgba="0 0 0 0" />
            </material>
        </visual>
    </link>
    <joint name="l_end_joint4" type="revolute">
        <origin rpy="0 1.5708 0" xyz="0 -0.001 0.0475" />
        <parent link="l_tool_end_Link" />
        <child link="l_end_Link4" />
        <axis xyz="1 0 0" />
        <limit effort="1000" lower="0" upper="0" velocity="6.5" />
        <dynamics damping="0.0" friction="10" />
    </joint>
    <link name="l_end_Link5">
        <gravity>0</gravity>
        <inertial>
            <origin rpy="0 0 0" xyz="0 0 0" />
            <mass value="0.0001" />
            <inertia ixx="0.0001" ixy="0.000" ixz="0.000" iyy="0.0001" iyz="0.000" izz="0.0001" />
        </inertial>
        <visual>
            <origin rpy="0 0 0" xyz="0 0 0" />
            <geometry>
                <box size="0.01 0.01 0.01" />
            </geometry>
            <material name="transparent">
                <color rgba="0 0 0 0" />
            </material>
        </visual>
    </link>
    <joint name="l_end_joint5" type="revolute">
        <origin rpy="0 1.5708 0" xyz="0 -0.001 0.0725" />
        <parent link="l_tool_end_Link" />
        <child link="l_end_Link5" />
        <axis xyz="1 0 0" />
        <limit effort="1000" lower="0" upper="0" velocity="6.5" />
        <dynamics damping="0.0" friction="10" />
    </joint>
    <transmission name="l_suction_tran">
        <type>transmission_interface/SimpleTransmission</type>
        <joint name="l_tool_joint">
            <hardwareInterface>hardware_interface/EffortJointInterface</hardwareInterface>
        </joint>
        <actuator name="l_suction_motor1">
            <hardwareInterface>hardware_interface/EffortJointInterface</hardwareInterface>
            <mechanicalReduction>1</mechanicalReduction>
        </actuator>
    </transmission>
    <!-- Link1 -->
    <gazebo reference="l_tool_link">
        <mu1>0.2</mu1>
        <mu2>0.2</mu2>
        <material>Gazebo/white</material>
        <selfCollide>false</selfCollide>
    </gazebo>
    <gazebo reference="l_tool_end_Link">
        <mu1>0.2</mu1>
        <mu2>0.2</mu2>
        <material>Gazebo/grey</material>
        <selfCollide>false</selfCollide>
    </gazebo>
    <!--joint name="fixed" type="fixed">
    <origin
      xyz="0 0.016 0"
      rpy="-1.57 1.57 0" />
    <parent link="Arm_Base_L_Link"/>
    <child link="Base"/>
  </joint-->
    <!--<joint name="fixed1" type="fixed">
    <origin
      xyz="0 0 0"
      rpy="0 0 0" />
    <parent link="mobile_base"/>
    <child link="base_link"/>
  </joint>-->
    <!--joint name="fixed2" type="fixed">
    <origin
      xyz="0 -0.016 0"
      rpy="1.57 1.57 0" />
    <parent link="Arm_Base_R_Link"/>
    <child link="Arm_Base_R"/>
  </joint-->
    <link name="Bin">
        <inertial>
            <origin rpy="0 0 0" xyz="0 0 0" />
            <mass value="0.823603974032196" />
            <inertia ixx="1" ixy="0" ixz="0" iyy="1" iyz="0" izz="1" />
        </inertial>
        <visual>
            <origin rpy="0 0 0" xyz="0 0 0" />
            <geometry>
                <mesh filename="package://mobile_dual_arm/scene/meshes/bin.STL" scale="0.001 0.001 0.001" />
            </geometry>
            <material name="blue_">
                <color rgba="0.4 0.66 0.99 1" />
            </material>
        </visual>
        <collision>
            <origin rpy="0 0 0" xyz="0 0 0" />
            <geometry>
                <mesh filename="package://mobile_dual_arm/scene/meshes/bin.STL" scale="0.001 0.001 0.001" />
            </geometry>
        </collision>
    </link>
    <joint name="fixed4" type="fixed">
        <origin rpy="0 0 1.5708" xyz="0.35 -0.31 0.26" />
        <parent link="base_link" />
        <child link="Bin" />
    </joint>
    <transmission name="trans_mobile_fl_caster_rotation_joint">
        <type>transmission_interface/SimpleTransmission</type>
        <joint name="mobile_fl_caster_rotation_joint">
            <hardwareInterface>hardware_interface/EffortJointInterface</hardwareInterface>
        </joint>
        <actuator name="mobile_fl_caster_rotation_joint_motor">
            <hardwareInterface>hardware_interface/EffortJointInterface</hardwareInterface>
            <mechanicalReduction>1</mechanicalReduction>
        </actuator>
    </transmission>
    <transmission name="trans_mobile_fl_caster_wheel_joint">
        <type>transmission_interface/SimpleTransmission</type>
        <joint name="mobile_fl_caster_wheel_joint">
            <hardwareInterface>hardware_interface/EffortJointInterface</hardwareInterface>
        </joint>
        <actuator name="mobile_fl_caster_wheel_joint_motor">
            <hardwareInterface>hardware_interface/EffortJointInterface</hardwareInterface>
            <mechanicalReduction>1</mechanicalReduction>
        </actuator>
    </transmission>
    <transmission name="trans_mobile_fr_caster_rotation_joint">
        <type>transmission_interface/SimpleTransmission</type>
        <joint name="mobile_fr_caster_rotation_joint">
            <hardwareInterface>hardware_interface/EffortJointInterface</hardwareInterface>
        </joint>
        <actuator name="mobile_fr_caster_rotation_joint_motor">
            <hardwareInterface>hardware_interface/EffortJointInterface</hardwareInterface>
            <mechanicalReduction>1</mechanicalReduction>
        </actuator>
    </transmission>
    <transmission name="trans_mobile_fr_caster_wheel_joint">
        <type>transmission_interface/SimpleTransmission</type>
        <joint name="mobile_fr_caster_wheel_joint">
            <hardwareInterface>hardware_interface/EffortJointInterface</hardwareInterface>
        </joint>
        <actuator name="mobile_fr_caster_wheel_joint_motor">
            <hardwareInterface>hardware_interface/EffortJointInterface</hardwareInterface>
            <mechanicalReduction>1</mechanicalReduction>
        </actuator>
    </transmission>
    <transmission name="trans_mobile_bl_caster_rotation_joint">
        <type>transmission_interface/SimpleTransmission</type>
        <joint name="mobile_bl_caster_rotation_joint">
            <hardwareInterface>hardware_interface/EffortJointInterface</hardwareInterface>
        </joint>
        <actuator name="mobile_bl_caster_rotation_joint_motor">
            <hardwareInterface>hardware_interface/EffortJointInterface</hardwareInterface>
            <mechanicalReduction>1</mechanicalReduction>
        </actuator>
    </transmission>
    <transmission name="trans_mobile_bl_caster_wheel_joint">
        <type>transmission_interface/SimpleTransmission</type>
        <joint name="mobile_bl_caster_wheel_joint">
            <hardwareInterface>hardware_interface/EffortJointInterface</hardwareInterface>
        </joint>
        <actuator name="mobile_bl_caster_wheel_joint_motor">
            <hardwareInterface>hardware_interface/EffortJointInterface</hardwareInterface>
            <mechanicalReduction>1</mechanicalReduction>
        </actuator>
    </transmission>
    <transmission name="trans_mobile_br_caster_rotation_joint">
        <type>transmission_interface/SimpleTransmission</type>
        <joint name="mobile_br_caster_rotation_joint">
            <hardwareInterface>hardware_interface/EffortJointInterface</hardwareInterface>
        </joint>
        <actuator name="mobile_br_caster_rotation_joint_motor">
            <hardwareInterface>hardware_interface/EffortJointInterface</hardwareInterface>
            <mechanicalReduction>1</mechanicalReduction>
        </actuator>
    </transmission>
    <transmission name="trans_mobile_br_caster_wheel_joint">
        <type>transmission_interface/SimpleTransmission</type>
        <joint name="mobile_br_caster_wheel_joint">
            <hardwareInterface>hardware_interface/EffortJointInterface</hardwareInterface>
        </joint>
        <actuator name="mobile_br_caster_wheel_joint_motor">
            <hardwareInterface>hardware_interface/EffortJointInterface</hardwareInterface>
            <mechanicalReduction>1</mechanicalReduction>
        </actuator>
    </transmission>
    <transmission name="trans_r_end_joint1">
        <type>transmission_interface/SimpleTransmission</type>
        <joint name="r_end_joint1">
            <hardwareInterface>hardware_interface/EffortJointInterface</hardwareInterface>
        </joint>
        <actuator name="r_end_joint1_motor">
            <hardwareInterface>hardware_interface/EffortJointInterface</hardwareInterface>
            <mechanicalReduction>1</mechanicalReduction>
        </actuator>
    </transmission>
    <transmission name="trans_r_end_joint2">
        <type>transmission_interface/SimpleTransmission</type>
        <joint name="r_end_joint2">
            <hardwareInterface>hardware_interface/EffortJointInterface</hardwareInterface>
        </joint>
        <actuator name="r_end_joint2_motor">
            <hardwareInterface>hardware_interface/EffortJointInterface</hardwareInterface>
            <mechanicalReduction>1</mechanicalReduction>
        </actuator>
    </transmission>
    <transmission name="trans_r_end_joint3">
        <type>transmission_interface/SimpleTransmission</type>
        <joint name="r_end_joint3">
            <hardwareInterface>hardware_interface/EffortJointInterface</hardwareInterface>
        </joint>
        <actuator name="r_end_joint3_motor">
            <hardwareInterface>hardware_interface/EffortJointInterface</hardwareInterface>
            <mechanicalReduction>1</mechanicalReduction>
        </actuator>
    </transmission>
    <transmission name="trans_r_end_joint4">
        <type>transmission_interface/SimpleTransmission</type>
        <joint name="r_end_joint4">
            <hardwareInterface>hardware_interface/EffortJointInterface</hardwareInterface>
        </joint>
        <actuator name="r_end_joint4_motor">
            <hardwareInterface>hardware_interface/EffortJointInterface</hardwareInterface>
            <mechanicalReduction>1</mechanicalReduction>
        </actuator>
    </transmission>
    <transmission name="trans_r_end_joint5">
        <type>transmission_interface/SimpleTransmission</type>
        <joint name="r_end_joint5">
            <hardwareInterface>hardware_interface/EffortJointInterface</hardwareInterface>
        </joint>
        <actuator name="r_end_joint5_motor">
            <hardwareInterface>hardware_interface/EffortJointInterface</hardwareInterface>
            <mechanicalReduction>1</mechanicalReduction>
        </actuator>
    </transmission>
    <transmission name="trans_l_end_joint1">
        <type>transmission_interface/SimpleTransmission</type>
        <joint name="l_end_joint1">
            <hardwareInterface>hardware_interface/EffortJointInterface</hardwareInterface>
        </joint>
        <actuator name="l_end_joint1_motor">
            <hardwareInterface>hardware_interface/EffortJointInterface</hardwareInterface>
            <mechanicalReduction>1</mechanicalReduction>
        </actuator>
    </transmission>
    <transmission name="trans_l_end_joint2">
        <type>transmission_interface/SimpleTransmission</type>
        <joint name="l_end_joint2">
            <hardwareInterface>hardware_interface/EffortJointInterface</hardwareInterface>
        </joint>
        <actuator name="l_end_joint2_motor">
            <hardwareInterface>hardware_interface/EffortJointInterface</hardwareInterface>
            <mechanicalReduction>1</mechanicalReduction>
        </actuator>
    </transmission>
    <transmission name="trans_l_end_joint3">
        <type>transmission_interface/SimpleTransmission</type>
        <joint name="l_end_joint3">
            <hardwareInterface>hardware_interface/EffortJointInterface</hardwareInterface>
        </joint>
        <actuator name="l_end_joint3_motor">
            <hardwareInterface>hardware_interface/EffortJointInterface</hardwareInterface>
            <mechanicalReduction>1</mechanicalReduction>
        </actuator>
    </transmission>
    <transmission name="trans_l_end_joint4">
        <type>transmission_interface/SimpleTransmission</type>
        <joint name="l_end_joint4">
            <hardwareInterface>hardware_interface/EffortJointInterface</hardwareInterface>
        </joint>
        <actuator name="l_end_joint4_motor">
            <hardwareInterface>hardware_interface/EffortJointInterface</hardwareInterface>
            <mechanicalReduction>1</mechanicalReduction>
        </actuator>
    </transmission>
    <transmission name="trans_l_end_joint5">
        <type>transmission_interface/SimpleTransmission</type>
        <joint name="l_end_joint5">
            <hardwareInterface>hardware_interface/EffortJointInterface</hardwareInterface>
        </joint>
        <actuator name="l_end_joint5_motor">
            <hardwareInterface>hardware_interface/EffortJointInterface</hardwareInterface>
            <mechanicalReduction>1</mechanicalReduction>
        </actuator>
    </transmission>
</robot>

